 2020-07-31 00:00:16,465 [P9088/D2/T11] INFO  Umbraco.Core.UmbracoApplicationBase - Application shutdown. Details: InitializationError

_shutDownMessage=Initialization Error
HostingEnvironment initiated shutdown
HostingEnvironment caused shutdown

_shutDownStack=   at System.Environment.GetStackTrace(Exception e, Boolean needFileInfo)
   at System.Environment.get_StackTrace()
   at System.Web.Hosting.HostingEnvironment.InitiateShutdownInternal()
   at System.Web.Hosting.HostingEnvironment.InitiateShutdownWithoutDemand()
   at System.Web.HttpRuntime.ShutdownAppDomain(String stackTrace)
   at System.Web.HttpRuntime.AppDomainShutdownTimerCallback(Object state)
   at System.Threading.ExecutionContext.RunInternal(ExecutionContext executionContext, ContextCallback callback, Object state, Boolean preserveSyncCtx)
   at System.Threading.ExecutionContext.Run(ExecutionContext executionContext, ContextCallback callback, Object state, Boolean preserveSyncCtx)
   at System.Threading.TimerQueueTimer.CallCallback()
   at System.Threading.TimerQueueTimer.Fire()
   at System.Threading.TimerQueue.FireNextTimers()
 2020-07-31 01:26:59,694 [P6272/D2/T1] INFO  Umbraco.Core.CoreBootManager - Umbraco 7.10.0 application starting on IP-208-109-15-4
 2020-07-31 01:26:59,725 [P6272/D2/T1] INFO  Umbraco.Core.PluginManager - Determining hash of code files on disk
 2020-07-31 01:26:59,741 [P6272/D2/T1] INFO  Umbraco.Core.PluginManager - Hash determined (took 10ms)
 2020-07-31 01:26:59,835 [P6272/D2/T1] INFO  Umbraco.Core.MainDom - Acquiring MainDom...
 2020-07-31 01:26:59,835 [P6272/D2/T1] INFO  Umbraco.Core.MainDom - Acquired MainDom.
 2020-07-31 01:26:59,835 [P6272/D2/T1] INFO  Umbraco.Core.PluginManager - Resolving umbraco.interfaces.IDiscoverable
 2020-07-31 01:26:59,897 [P6272/D2/T1] INFO  Umbraco.Core.PluginManager - Resolved umbraco.interfaces.IDiscoverable (took 62ms)
 2020-07-31 01:26:59,897 [P6272/D2/T1] INFO  Umbraco.Core.PluginManager - Resolving umbraco.interfaces.IApplicationStartupHandler
 2020-07-31 01:26:59,897 [P6272/D2/T1] INFO  Umbraco.Core.PluginManager - Resolved umbraco.interfaces.IApplicationStartupHandler (took 1ms)
 2020-07-31 01:26:59,928 [P6272/D2/T1] INFO  Umbraco.Core.PluginManager - Resolving umbraco.interfaces.IDiscoverable
 2020-07-31 01:26:59,944 [P6272/D2/T1] INFO  Umbraco.Core.PluginManager - Resolved umbraco.interfaces.IDiscoverable (took 0ms)
 2020-07-31 01:26:59,944 [P6272/D2/T1] INFO  Umbraco.Core.PluginManager - Resolving Umbraco.Core.PropertyEditors.IPropertyEditorValueConverter
 2020-07-31 01:26:59,944 [P6272/D2/T1] INFO  Umbraco.Core.PluginManager - Resolved Umbraco.Core.PropertyEditors.IPropertyEditorValueConverter (took 0ms)
 2020-07-31 01:26:59,944 [P6272/D2/T1] INFO  Umbraco.Core.PluginManager - Resolving umbraco.interfaces.IDiscoverable
 2020-07-31 01:26:59,944 [P6272/D2/T1] INFO  Umbraco.Core.PluginManager - Resolved umbraco.interfaces.IDiscoverable (took 0ms)
 2020-07-31 01:26:59,944 [P6272/D2/T1] INFO  Umbraco.Core.PluginManager - Resolving Umbraco.Core.PropertyEditors.IPropertyValueConverter
 2020-07-31 01:26:59,944 [P6272/D2/T1] INFO  Umbraco.Core.PluginManager - Resolved Umbraco.Core.PropertyEditors.IPropertyValueConverter (took 1ms)
 2020-07-31 01:26:59,960 [P6272/D2/T1] INFO  Umbraco.Core.PluginManager - Resolving umbraco.interfaces.IDiscoverable
 2020-07-31 01:26:59,960 [P6272/D2/T1] INFO  Umbraco.Core.PluginManager - Resolved umbraco.interfaces.IDiscoverable (took 0ms)
 2020-07-31 01:26:59,960 [P6272/D2/T1] INFO  Umbraco.Core.PluginManager - Resolving Umbraco.Web.Mvc.SurfaceController
 2020-07-31 01:26:59,960 [P6272/D2/T1] INFO  Umbraco.Core.PluginManager - Resolved Umbraco.Web.Mvc.SurfaceController (took 0ms)
 2020-07-31 01:26:59,960 [P6272/D2/T1] INFO  Umbraco.Core.PluginManager - Resolving umbraco.interfaces.IDiscoverable
 2020-07-31 01:26:59,960 [P6272/D2/T1] INFO  Umbraco.Core.PluginManager - Resolved umbraco.interfaces.IDiscoverable (took 0ms)
 2020-07-31 01:26:59,960 [P6272/D2/T1] INFO  Umbraco.Core.PluginManager - Resolving Umbraco.Web.WebApi.UmbracoApiController
 2020-07-31 01:26:59,960 [P6272/D2/T1] INFO  Umbraco.Core.PluginManager - Resolved Umbraco.Web.WebApi.UmbracoApiController (took 0ms)
 2020-07-31 01:27:26,053 [P6272/D2/T1] WARN  Umbraco.Core.Persistence.DbConnectionExtensions - Configured database is reporting as not being available! DataSource: 108.60.212.192, InitialCatalog: LFZ_Web. Exception: System.Data.SqlClient.SqlException (0x80131904): A network-related or instance-specific error occurred while establishing a connection to SQL Server. The server was not found or was not accessible. Verify that the instance name is correct and that SQL Server is configured to allow remote connections. (provider: Named Pipes Provider, error: 40 - Could not open a connection to SQL Server) ---> System.ComponentModel.Win32Exception (0x80004005): The network path was not found
   at System.Data.SqlClient.SqlInternalConnectionTds..ctor(DbConnectionPoolIdentity identity, SqlConnectionString connectionOptions, SqlCredential credential, Object providerInfo, String newPassword, SecureString newSecurePassword, Boolean redirectedUserInstance, SqlConnectionString userConnectionOptions, SessionData reconnectSessionData, DbConnectionPool pool, String accessToken, Boolean applyTransientFaultHandling, SqlAuthenticationProviderManager sqlAuthProviderManager)
   at System.Data.SqlClient.SqlConnectionFactory.CreateConnection(DbConnectionOptions options, DbConnectionPoolKey poolKey, Object poolGroupProviderInfo, DbConnectionPool pool, DbConnection owningConnection, DbConnectionOptions userOptions)
   at System.Data.ProviderBase.DbConnectionFactory.CreatePooledConnection(DbConnectionPool pool, DbConnection owningObject, DbConnectionOptions options, DbConnectionPoolKey poolKey, DbConnectionOptions userOptions)
   at System.Data.ProviderBase.DbConnectionPool.CreateObject(DbConnection owningObject, DbConnectionOptions userOptions, DbConnectionInternal oldConnection)
   at System.Data.ProviderBase.DbConnectionPool.UserCreateRequest(DbConnection owningObject, DbConnectionOptions userOptions, DbConnectionInternal oldConnection)
   at System.Data.ProviderBase.DbConnectionPool.TryGetConnection(DbConnection owningObject, UInt32 waitForMultipleObjectsTimeout, Boolean allowCreate, Boolean onlyOneCheckConnection, DbConnectionOptions userOptions, DbConnectionInternal& connection)
   at System.Data.ProviderBase.DbConnectionPool.TryGetConnection(DbConnection owningObject, TaskCompletionSource`1 retry, DbConnectionOptions userOptions, DbConnectionInternal& connection)
   at System.Data.ProviderBase.DbConnectionFactory.TryGetConnection(DbConnection owningConnection, TaskCompletionSource`1 retry, DbConnectionOptions userOptions, DbConnectionInternal oldConnection, DbConnectionInternal& connection)
   at System.Data.ProviderBase.DbConnectionInternal.TryOpenConnectionInternal(DbConnection outerConnection, DbConnectionFactory connectionFactory, TaskCompletionSource`1 retry, DbConnectionOptions userOptions)
   at System.Data.SqlClient.SqlConnection.TryOpenInner(TaskCompletionSource`1 retry)
   at System.Data.SqlClient.SqlConnection.TryOpen(TaskCompletionSource`1 retry)
   at System.Data.SqlClient.SqlConnection.Open()
   at Umbraco.Core.Persistence.DbConnectionExtensions.IsAvailable(IDbConnection connection)
ClientConnectionId:00000000-0000-0000-0000-000000000000
Error Number:53,State:0,Class:20
 2020-07-31 01:27:26,053 [P6272/D2/T1] INFO  Umbraco.Core.DatabaseContext - CanConnect = False
 2020-07-31 01:27:26,209 [P6272/D2/T1] WARN  Umbraco.Core.Persistence.DbConnectionExtensions - Configured database is reporting as not being available! DataSource: 108.60.212.192, InitialCatalog: LFZ_Web. Exception: System.Data.SqlClient.SqlException (0x80131904): A network-related or instance-specific error occurred while establishing a connection to SQL Server. The server was not found or was not accessible. Verify that the instance name is correct and that SQL Server is configured to allow remote connections. (provider: Named Pipes Provider, error: 40 - Could not open a connection to SQL Server) ---> System.ComponentModel.Win32Exception (0x80004005): The network path was not found
   at System.Data.ProviderBase.DbConnectionPool.TryGetConnection(DbConnection owningObject, UInt32 waitForMultipleObjectsTimeout, Boolean allowCreate, Boolean onlyOneCheckConnection, DbConnectionOptions userOptions, DbConnectionInternal& connection)
   at System.Data.ProviderBase.DbConnectionPool.TryGetConnection(DbConnection owningObject, TaskCompletionSource`1 retry, DbConnectionOptions userOptions, DbConnectionInternal& connection)
   at System.Data.ProviderBase.DbConnectionFactory.TryGetConnection(DbConnection owningConnection, TaskCompletionSource`1 retry, DbConnectionOptions userOptions, DbConnectionInternal oldConnection, DbConnectionInternal& connection)
   at System.Data.ProviderBase.DbConnectionInternal.TryOpenConnectionInternal(DbConnection outerConnection, DbConnectionFactory connectionFactory, TaskCompletionSource`1 retry, DbConnectionOptions userOptions)
   at System.Data.SqlClient.SqlConnection.TryOpenInner(TaskCompletionSource`1 retry)
   at System.Data.SqlClient.SqlConnection.TryOpen(TaskCompletionSource`1 retry)
   at System.Data.SqlClient.SqlConnection.Open()
   at Umbraco.Core.Persistence.DbConnectionExtensions.IsAvailable(IDbConnection connection)
ClientConnectionId:00000000-0000-0000-0000-000000000000
Error Number:53,State:0,Class:20
 2020-07-31 01:27:26,209 [P6272/D2/T1] INFO  Umbraco.Core.DatabaseContext - CanConnect = False
 2020-07-31 01:27:27,225 [P6272/D2/T1] WARN  Umbraco.Core.Persistence.DbConnectionExtensions - Configured database is reporting as not being available! DataSource: 108.60.212.192, InitialCatalog: LFZ_Web. Exception: System.Data.SqlClient.SqlException (0x80131904): A network-related or instance-specific error occurred while establishing a connection to SQL Server. The server was not found or was not accessible. Verify that the instance name is correct and that SQL Server is configured to allow remote connections. (provider: Named Pipes Provider, error: 40 - Could not open a connection to SQL Server) ---> System.ComponentModel.Win32Exception (0x80004005): The network path was not found
   at System.Data.ProviderBase.DbConnectionPool.TryGetConnection(DbConnection owningObject, UInt32 waitForMultipleObjectsTimeout, Boolean allowCreate, Boolean onlyOneCheckConnection, DbConnectionOptions userOptions, DbConnectionInternal& connection)
   at System.Data.ProviderBase.DbConnectionPool.TryGetConnection(DbConnection owningObject, TaskCompletionSource`1 retry, DbConnectionOptions userOptions, DbConnectionInternal& connection)
   at System.Data.ProviderBase.DbConnectionFactory.TryGetConnection(DbConnection owningConnection, TaskCompletionSource`1 retry, DbConnectionOptions userOptions, DbConnectionInternal oldConnection, DbConnectionInternal& connection)
   at System.Data.ProviderBase.DbConnectionInternal.TryOpenConnectionInternal(DbConnection outerConnection, DbConnectionFactory connectionFactory, TaskCompletionSource`1 retry, DbConnectionOptions userOptions)
   at System.Data.SqlClient.SqlConnection.TryOpenInner(TaskCompletionSource`1 retry)
   at System.Data.SqlClient.SqlConnection.TryOpen(TaskCompletionSource`1 retry)
   at System.Data.SqlClient.SqlConnection.Open()
   at Umbraco.Core.Persistence.DbConnectionExtensions.IsAvailable(IDbConnection connection)
ClientConnectionId:00000000-0000-0000-0000-000000000000
Error Number:53,State:0,Class:20
 2020-07-31 01:27:27,225 [P6272/D2/T1] INFO  Umbraco.Core.DatabaseContext - CanConnect = False
 2020-07-31 01:27:28,241 [P6272/D2/T1] WARN  Umbraco.Core.Persistence.DbConnectionExtensions - Configured database is reporting as not being available! DataSource: 108.60.212.192, InitialCatalog: LFZ_Web. Exception: System.Data.SqlClient.SqlException (0x80131904): A network-related or instance-specific error occurred while establishing a connection to SQL Server. The server was not found or was not accessible. Verify that the instance name is correct and that SQL Server is configured to allow remote connections. (provider: Named Pipes Provider, error: 40 - Could not open a connection to SQL Server) ---> System.ComponentModel.Win32Exception (0x80004005): The network path was not found
   at System.Data.ProviderBase.DbConnectionPool.TryGetConnection(DbConnection owningObject, UInt32 waitForMultipleObjectsTimeout, Boolean allowCreate, Boolean onlyOneCheckConnection, DbConnectionOptions userOptions, DbConnectionInternal& connection)
   at System.Data.ProviderBase.DbConnectionPool.TryGetConnection(DbConnection owningObject, TaskCompletionSource`1 retry, DbConnectionOptions userOptions, DbConnectionInternal& connection)
   at System.Data.ProviderBase.DbConnectionFactory.TryGetConnection(DbConnection owningConnection, TaskCompletionSource`1 retry, DbConnectionOptions userOptions, DbConnectionInternal oldConnection, DbConnectionInternal& connection)
   at System.Data.ProviderBase.DbConnectionInternal.TryOpenConnectionInternal(DbConnection outerConnection, DbConnectionFactory connectionFactory, TaskCompletionSource`1 retry, DbConnectionOptions userOptions)
   at System.Data.SqlClient.SqlConnection.TryOpenInner(TaskCompletionSource`1 retry)
   at System.Data.SqlClient.SqlConnection.TryOpen(TaskCompletionSource`1 retry)
   at System.Data.SqlClient.SqlConnection.Open()
   at Umbraco.Core.Persistence.DbConnectionExtensions.IsAvailable(IDbConnection connection)
ClientConnectionId:00000000-0000-0000-0000-000000000000
Error Number:53,State:0,Class:20
 2020-07-31 01:27:28,241 [P6272/D2/T1] INFO  Umbraco.Core.DatabaseContext - CanConnect = False
 2020-07-31 01:27:29,256 [P6272/D2/T1] WARN  Umbraco.Core.Persistence.DbConnectionExtensions - Configured database is reporting as not being available! DataSource: 108.60.212.192, InitialCatalog: LFZ_Web. Exception: System.Data.SqlClient.SqlException (0x80131904): A network-related or instance-specific error occurred while establishing a connection to SQL Server. The server was not found or was not accessible. Verify that the instance name is correct and that SQL Server is configured to allow remote connections. (provider: Named Pipes Provider, error: 40 - Could not open a connection to SQL Server) ---> System.ComponentModel.Win32Exception (0x80004005): The network path was not found
   at System.Data.ProviderBase.DbConnectionPool.TryGetConnection(DbConnection owningObject, UInt32 waitForMultipleObjectsTimeout, Boolean allowCreate, Boolean onlyOneCheckConnection, DbConnectionOptions userOptions, DbConnectionInternal& connection)
   at System.Data.ProviderBase.DbConnectionPool.TryGetConnection(DbConnection owningObject, TaskCompletionSource`1 retry, DbConnectionOptions userOptions, DbConnectionInternal& connection)
   at System.Data.ProviderBase.DbConnectionFactory.TryGetConnection(DbConnection owningConnection, TaskCompletionSource`1 retry, DbConnectionOptions userOptions, DbConnectionInternal oldConnection, DbConnectionInternal& connection)
   at System.Data.ProviderBase.DbConnectionInternal.TryOpenConnectionInternal(DbConnection outerConnection, DbConnectionFactory connectionFactory, TaskCompletionSource`1 retry, DbConnectionOptions userOptions)
   at System.Data.SqlClient.SqlConnection.TryOpenInner(TaskCompletionSource`1 retry)
   at System.Data.SqlClient.SqlConnection.TryOpen(TaskCompletionSource`1 retry)
   at System.Data.SqlClient.SqlConnection.Open()
   at Umbraco.Core.Persistence.DbConnectionExtensions.IsAvailable(IDbConnection connection)
ClientConnectionId:00000000-0000-0000-0000-000000000000
Error Number:53,State:0,Class:20
 2020-07-31 01:27:29,256 [P6272/D2/T1] INFO  Umbraco.Core.DatabaseContext - CanConnect = False
 2020-07-31 01:27:30,272 [P6272/D2/T1] WARN  Umbraco.Core.Persistence.DbConnectionExtensions - Configured database is reporting as not being available! DataSource: 108.60.212.192, InitialCatalog: LFZ_Web. Exception: System.Data.SqlClient.SqlException (0x80131904): A network-related or instance-specific error occurred while establishing a connection to SQL Server. The server was not found or was not accessible. Verify that the instance name is correct and that SQL Server is configured to allow remote connections. (provider: Named Pipes Provider, error: 40 - Could not open a connection to SQL Server) ---> System.ComponentModel.Win32Exception (0x80004005): The network path was not found
   at System.Data.ProviderBase.DbConnectionPool.TryGetConnection(DbConnection owningObject, UInt32 waitForMultipleObjectsTimeout, Boolean allowCreate, Boolean onlyOneCheckConnection, DbConnectionOptions userOptions, DbConnectionInternal& connection)
   at System.Data.ProviderBase.DbConnectionPool.TryGetConnection(DbConnection owningObject, TaskCompletionSource`1 retry, DbConnectionOptions userOptions, DbConnectionInternal& connection)
   at System.Data.ProviderBase.DbConnectionFactory.TryGetConnection(DbConnection owningConnection, TaskCompletionSource`1 retry, DbConnectionOptions userOptions, DbConnectionInternal oldConnection, DbConnectionInternal& connection)
   at System.Data.ProviderBase.DbConnectionInternal.TryOpenConnectionInternal(DbConnection outerConnection, DbConnectionFactory connectionFactory, TaskCompletionSource`1 retry, DbConnectionOptions userOptions)
   at System.Data.SqlClient.SqlConnection.TryOpenInner(TaskCompletionSource`1 retry)
   at System.Data.SqlClient.SqlConnection.TryOpen(TaskCompletionSource`1 retry)
   at System.Data.SqlClient.SqlConnection.Open()
   at Umbraco.Core.Persistence.DbConnectionExtensions.IsAvailable(IDbConnection connection)
ClientConnectionId:00000000-0000-0000-0000-000000000000
Error Number:53,State:0,Class:20
 2020-07-31 01:27:30,272 [P6272/D2/T1] INFO  Umbraco.Core.DatabaseContext - CanConnect = False
 2020-07-31 01:27:47,053 [P6272/D2/T1] WARN  Umbraco.Core.Persistence.DbConnectionExtensions - Configured database is reporting as not being available! DataSource: 108.60.212.192, InitialCatalog: LFZ_Web. Exception: System.Data.SqlClient.SqlException (0x80131904): A network-related or instance-specific error occurred while establishing a connection to SQL Server. The server was not found or was not accessible. Verify that the instance name is correct and that SQL Server is configured to allow remote connections. (provider: Named Pipes Provider, error: 40 - Could not open a connection to SQL Server) ---> System.ComponentModel.Win32Exception (0x80004005): The network path was not found
   at System.Data.SqlClient.SqlInternalConnectionTds..ctor(DbConnectionPoolIdentity identity, SqlConnectionString connectionOptions, SqlCredential credential, Object providerInfo, String newPassword, SecureString newSecurePassword, Boolean redirectedUserInstance, SqlConnectionString userConnectionOptions, SessionData reconnectSessionData, DbConnectionPool pool, String accessToken, Boolean applyTransientFaultHandling, SqlAuthenticationProviderManager sqlAuthProviderManager)
   at System.Data.SqlClient.SqlConnectionFactory.CreateConnection(DbConnectionOptions options, DbConnectionPoolKey poolKey, Object poolGroupProviderInfo, DbConnectionPool pool, DbConnection owningConnection, DbConnectionOptions userOptions)
   at System.Data.ProviderBase.DbConnectionFactory.CreatePooledConnection(DbConnectionPool pool, DbConnection owningObject, DbConnectionOptions options, DbConnectionPoolKey poolKey, DbConnectionOptions userOptions)
   at System.Data.ProviderBase.DbConnectionPool.CreateObject(DbConnection owningObject, DbConnectionOptions userOptions, DbConnectionInternal oldConnection)
   at System.Data.ProviderBase.DbConnectionPool.UserCreateRequest(DbConnection owningObject, DbConnectionOptions userOptions, DbConnectionInternal oldConnection)
   at System.Data.ProviderBase.DbConnectionPool.TryGetConnection(DbConnection owningObject, UInt32 waitForMultipleObjectsTimeout, Boolean allowCreate, Boolean onlyOneCheckConnection, DbConnectionOptions userOptions, DbConnectionInternal& connection)
   at System.Data.ProviderBase.DbConnectionPool.TryGetConnection(DbConnection owningObject, TaskCompletionSource`1 retry, DbConnectionOptions userOptions, DbConnectionInternal& connection)
   at System.Data.ProviderBase.DbConnectionFactory.TryGetConnection(DbConnection owningConnection, TaskCompletionSource`1 retry, DbConnectionOptions userOptions, DbConnectionInternal oldConnection, DbConnectionInternal& connection)
   at System.Data.ProviderBase.DbConnectionInternal.TryOpenConnectionInternal(DbConnection outerConnection, DbConnectionFactory connectionFactory, TaskCompletionSource`1 retry, DbConnectionOptions userOptions)
   at System.Data.SqlClient.SqlConnection.TryOpenInner(TaskCompletionSource`1 retry)
   at System.Data.SqlClient.SqlConnection.TryOpen(TaskCompletionSource`1 retry)
   at System.Data.SqlClient.SqlConnection.Open()
   at Umbraco.Core.Persistence.DbConnectionExtensions.IsAvailable(IDbConnection connection)
ClientConnectionId:00000000-0000-0000-0000-000000000000
Error Number:53,State:0,Class:20
 2020-07-31 01:27:47,053 [P6272/D2/T1] INFO  Umbraco.Core.DatabaseContext - CanConnect = False
 2020-07-31 01:27:47,053 [P6272/D2/T1] ERROR Umbraco.Core.UmbracoApplicationBase - An unhandled exception occurred
Umbraco.Core.Exceptions.UmbracoStartupFailedException: Umbraco cannot start. A connection string is configured but Umbraco cannot connect to the database.
   at Umbraco.Core.CoreBootManager.EnsureDatabaseConnection()
   at Umbraco.Core.CoreBootManager.Complete(Action`1 afterComplete)
   at Umbraco.Web.WebBootManager.Complete(Action`1 afterComplete)
   at Umbraco.Core.UmbracoApplicationBase.StartApplication(Object sender, EventArgs e)
 2020-07-31 01:27:57,069 [P6272/D2/T11] INFO  Umbraco.Core.MainDom - Stopping...
 2020-07-31 01:27:57,069 [P6272/D2/T11] INFO  Umbraco.Web.ExamineStartup - Examine shutting down
 2020-07-31 01:27:57,240 [P6272/D2/T11] INFO  Umbraco.Web.ExamineStartup - Complete (took 178ms)
 2020-07-31 01:27:57,240 [P6272/D2/T11] INFO  Umbraco.Core.MainDom - Released MainDom.
 2020-07-31 01:28:27,256 [P6272/D2/T14] INFO  Umbraco.Core.UmbracoApplicationBase - Application shutdown. Details: InitializationError

_shutDownMessage=Initialization Error
HostingEnvironment initiated shutdown
HostingEnvironment caused shutdown

_shutDownStack=   at System.Environment.GetStackTrace(Exception e, Boolean needFileInfo)
   at System.Environment.get_StackTrace()
   at System.Web.Hosting.HostingEnvironment.InitiateShutdownInternal()
   at System.Web.Hosting.HostingEnvironment.InitiateShutdownWithoutDemand()
   at System.Web.HttpRuntime.ShutdownAppDomain(String stackTrace)
   at System.Web.HttpRuntime.AppDomainShutdownTimerCallback(Object state)
   at System.Threading.ExecutionContext.RunInternal(ExecutionContext executionContext, ContextCallback callback, Object state, Boolean preserveSyncCtx)
   at System.Threading.ExecutionContext.Run(ExecutionContext executionContext, ContextCallback callback, Object state, Boolean preserveSyncCtx)
   at System.Threading.TimerQueueTimer.CallCallback()
   at System.Threading.TimerQueueTimer.Fire()
   at System.Threading.TimerQueue.FireNextTimers()
 2020-07-31 02:30:57,985 [P5912/D2/T1] INFO  Umbraco.Core.CoreBootManager - Umbraco 7.10.0 application starting on IP-208-109-15-4
 2020-07-31 02:30:57,985 [P5912/D2/T1] INFO  Umbraco.Core.PluginManager - Determining hash of code files on disk
 2020-07-31 02:30:57,985 [P5912/D2/T1] INFO  Umbraco.Core.PluginManager - Hash determined (took 4ms)
 2020-07-31 02:30:58,032 [P5912/D2/T1] INFO  Umbraco.Core.MainDom - Acquiring MainDom...
 2020-07-31 02:30:58,032 [P5912/D2/T1] INFO  Umbraco.Core.MainDom - Acquired MainDom.
 2020-07-31 02:30:58,032 [P5912/D2/T1] INFO  Umbraco.Core.PluginManager - Resolving umbraco.interfaces.IDiscoverable
 2020-07-31 02:30:58,095 [P5912/D2/T1] INFO  Umbraco.Core.PluginManager - Resolved umbraco.interfaces.IDiscoverable (took 69ms)
 2020-07-31 02:30:58,095 [P5912/D2/T1] INFO  Umbraco.Core.PluginManager - Resolving umbraco.interfaces.IApplicationStartupHandler
 2020-07-31 02:30:58,110 [P5912/D2/T1] INFO  Umbraco.Core.PluginManager - Resolved umbraco.interfaces.IApplicationStartupHandler (took 1ms)
 2020-07-31 02:30:58,142 [P5912/D2/T1] INFO  Umbraco.Core.PluginManager - Resolving umbraco.interfaces.IDiscoverable
 2020-07-31 02:30:58,142 [P5912/D2/T1] INFO  Umbraco.Core.PluginManager - Resolved umbraco.interfaces.IDiscoverable (took 1ms)
 2020-07-31 02:30:58,142 [P5912/D2/T1] INFO  Umbraco.Core.PluginManager - Resolving Umbraco.Core.PropertyEditors.IPropertyEditorValueConverter
 2020-07-31 02:30:58,142 [P5912/D2/T1] INFO  Umbraco.Core.PluginManager - Resolved Umbraco.Core.PropertyEditors.IPropertyEditorValueConverter (took 0ms)
 2020-07-31 02:30:58,142 [P5912/D2/T1] INFO  Umbraco.Core.PluginManager - Resolving umbraco.interfaces.IDiscoverable
 2020-07-31 02:30:58,142 [P5912/D2/T1] INFO  Umbraco.Core.PluginManager - Resolved umbraco.interfaces.IDiscoverable (took 0ms)
 2020-07-31 02:30:58,142 [P5912/D2/T1] INFO  Umbraco.Core.PluginManager - Resolving Umbraco.Core.PropertyEditors.IPropertyValueConverter
 2020-07-31 02:30:58,142 [P5912/D2/T1] INFO  Umbraco.Core.PluginManager - Resolved Umbraco.Core.PropertyEditors.IPropertyValueConverter (took 1ms)
 2020-07-31 02:30:58,157 [P5912/D2/T1] INFO  Umbraco.Core.PluginManager - Resolving umbraco.interfaces.IDiscoverable
 2020-07-31 02:30:58,157 [P5912/D2/T1] INFO  Umbraco.Core.PluginManager - Resolved umbraco.interfaces.IDiscoverable (took 0ms)
 2020-07-31 02:30:58,157 [P5912/D2/T1] INFO  Umbraco.Core.PluginManager - Resolving Umbraco.Web.Mvc.SurfaceController
 2020-07-31 02:30:58,157 [P5912/D2/T1] INFO  Umbraco.Core.PluginManager - Resolved Umbraco.Web.Mvc.SurfaceController (took 0ms)
 2020-07-31 02:30:58,157 [P5912/D2/T1] INFO  Umbraco.Core.PluginManager - Resolving umbraco.interfaces.IDiscoverable
 2020-07-31 02:30:58,173 [P5912/D2/T1] INFO  Umbraco.Core.PluginManager - Resolved umbraco.interfaces.IDiscoverable (took 0ms)
 2020-07-31 02:30:58,173 [P5912/D2/T1] INFO  Umbraco.Core.PluginManager - Resolving Umbraco.Web.WebApi.UmbracoApiController
 2020-07-31 02:30:58,173 [P5912/D2/T1] INFO  Umbraco.Core.PluginManager - Resolved Umbraco.Web.WebApi.UmbracoApiController (took 0ms)
 2020-07-31 02:31:24,282 [P5912/D2/T1] WARN  Umbraco.Core.Persistence.DbConnectionExtensions - Configured database is reporting as not being available! DataSource: 108.60.212.192, InitialCatalog: LFZ_Web. Exception: System.Data.SqlClient.SqlException (0x80131904): A network-related or instance-specific error occurred while establishing a connection to SQL Server. The server was not found or was not accessible. Verify that the instance name is correct and that SQL Server is configured to allow remote connections. (provider: Named Pipes Provider, error: 40 - Could not open a connection to SQL Server) ---> System.ComponentModel.Win32Exception (0x80004005): The network path was not found
   at System.Data.SqlClient.SqlInternalConnectionTds..ctor(DbConnectionPoolIdentity identity, SqlConnectionString connectionOptions, SqlCredential credential, Object providerInfo, String newPassword, SecureString newSecurePassword, Boolean redirectedUserInstance, SqlConnectionString userConnectionOptions, SessionData reconnectSessionData, DbConnectionPool pool, String accessToken, Boolean applyTransientFaultHandling, SqlAuthenticationProviderManager sqlAuthProviderManager)
   at System.Data.SqlClient.SqlConnectionFactory.CreateConnection(DbConnectionOptions options, DbConnectionPoolKey poolKey, Object poolGroupProviderInfo, DbConnectionPool pool, DbConnection owningConnection, DbConnectionOptions userOptions)
   at System.Data.ProviderBase.DbConnectionFactory.CreatePooledConnection(DbConnectionPool pool, DbConnection owningObject, DbConnectionOptions options, DbConnectionPoolKey poolKey, DbConnectionOptions userOptions)
   at System.Data.ProviderBase.DbConnectionPool.CreateObject(DbConnection owningObject, DbConnectionOptions userOptions, DbConnectionInternal oldConnection)
   at System.Data.ProviderBase.DbConnectionPool.UserCreateRequest(DbConnection owningObject, DbConnectionOptions userOptions, DbConnectionInternal oldConnection)
   at System.Data.ProviderBase.DbConnectionPool.TryGetConnection(DbConnection owningObject, UInt32 waitForMultipleObjectsTimeout, Boolean allowCreate, Boolean onlyOneCheckConnection, DbConnectionOptions userOptions, DbConnectionInternal& connection)
   at System.Data.ProviderBase.DbConnectionPool.TryGetConnection(DbConnection owningObject, TaskCompletionSource`1 retry, DbConnectionOptions userOptions, DbConnectionInternal& connection)
   at System.Data.ProviderBase.DbConnectionFactory.TryGetConnection(DbConnection owningConnection, TaskCompletionSource`1 retry, DbConnectionOptions userOptions, DbConnectionInternal oldConnection, DbConnectionInternal& connection)
   at System.Data.ProviderBase.DbConnectionInternal.TryOpenConnectionInternal(DbConnection outerConnection, DbConnectionFactory connectionFactory, TaskCompletionSource`1 retry, DbConnectionOptions userOptions)
   at System.Data.SqlClient.SqlConnection.TryOpenInner(TaskCompletionSource`1 retry)
   at System.Data.SqlClient.SqlConnection.TryOpen(TaskCompletionSource`1 retry)
   at System.Data.SqlClient.SqlConnection.Open()
   at Umbraco.Core.Persistence.DbConnectionExtensions.IsAvailable(IDbConnection connection)
ClientConnectionId:00000000-0000-0000-0000-000000000000
Error Number:53,State:0,Class:20
 2020-07-31 02:31:24,282 [P5912/D2/T1] INFO  Umbraco.Core.DatabaseContext - CanConnect = False
 2020-07-31 02:31:24,454 [P5912/D2/T1] WARN  Umbraco.Core.Persistence.DbConnectionExtensions - Configured database is reporting as not being available! DataSource: 108.60.212.192, InitialCatalog: LFZ_Web. Exception: System.Data.SqlClient.SqlException (0x80131904): A network-related or instance-specific error occurred while establishing a connection to SQL Server. The server was not found or was not accessible. Verify that the instance name is correct and that SQL Server is configured to allow remote connections. (provider: Named Pipes Provider, error: 40 - Could not open a connection to SQL Server) ---> System.ComponentModel.Win32Exception (0x80004005): The network path was not found
   at System.Data.ProviderBase.DbConnectionPool.TryGetConnection(DbConnection owningObject, UInt32 waitForMultipleObjectsTimeout, Boolean allowCreate, Boolean onlyOneCheckConnection, DbConnectionOptions userOptions, DbConnectionInternal& connection)
   at System.Data.ProviderBase.DbConnectionPool.TryGetConnection(DbConnection owningObject, TaskCompletionSource`1 retry, DbConnectionOptions userOptions, DbConnectionInternal& connection)
   at System.Data.ProviderBase.DbConnectionFactory.TryGetConnection(DbConnection owningConnection, TaskCompletionSource`1 retry, DbConnectionOptions userOptions, DbConnectionInternal oldConnection, DbConnectionInternal& connection)
   at System.Data.ProviderBase.DbConnectionInternal.TryOpenConnectionInternal(DbConnection outerConnection, DbConnectionFactory connectionFactory, TaskCompletionSource`1 retry, DbConnectionOptions userOptions)
   at System.Data.SqlClient.SqlConnection.TryOpenInner(TaskCompletionSource`1 retry)
   at System.Data.SqlClient.SqlConnection.TryOpen(TaskCompletionSource`1 retry)
   at System.Data.SqlClient.SqlConnection.Open()
   at Umbraco.Core.Persistence.DbConnectionExtensions.IsAvailable(IDbConnection connection)
ClientConnectionId:00000000-0000-0000-0000-000000000000
Error Number:53,State:0,Class:20
 2020-07-31 02:31:24,454 [P5912/D2/T1] INFO  Umbraco.Core.DatabaseContext - CanConnect = False
 2020-07-31 02:31:25,470 [P5912/D2/T1] WARN  Umbraco.Core.Persistence.DbConnectionExtensions - Configured database is reporting as not being available! DataSource: 108.60.212.192, InitialCatalog: LFZ_Web. Exception: System.Data.SqlClient.SqlException (0x80131904): A network-related or instance-specific error occurred while establishing a connection to SQL Server. The server was not found or was not accessible. Verify that the instance name is correct and that SQL Server is configured to allow remote connections. (provider: Named Pipes Provider, error: 40 - Could not open a connection to SQL Server) ---> System.ComponentModel.Win32Exception (0x80004005): The network path was not found
   at System.Data.ProviderBase.DbConnectionPool.TryGetConnection(DbConnection owningObject, UInt32 waitForMultipleObjectsTimeout, Boolean allowCreate, Boolean onlyOneCheckConnection, DbConnectionOptions userOptions, DbConnectionInternal& connection)
   at System.Data.ProviderBase.DbConnectionPool.TryGetConnection(DbConnection owningObject, TaskCompletionSource`1 retry, DbConnectionOptions userOptions, DbConnectionInternal& connection)
   at System.Data.ProviderBase.DbConnectionFactory.TryGetConnection(DbConnection owningConnection, TaskCompletionSource`1 retry, DbConnectionOptions userOptions, DbConnectionInternal oldConnection, DbConnectionInternal& connection)
   at System.Data.ProviderBase.DbConnectionInternal.TryOpenConnectionInternal(DbConnection outerConnection, DbConnectionFactory connectionFactory, TaskCompletionSource`1 retry, DbConnectionOptions userOptions)
   at System.Data.SqlClient.SqlConnection.TryOpenInner(TaskCompletionSource`1 retry)
   at System.Data.SqlClient.SqlConnection.TryOpen(TaskCompletionSource`1 retry)
   at System.Data.SqlClient.SqlConnection.Open()
   at Umbraco.Core.Persistence.DbConnectionExtensions.IsAvailable(IDbConnection connection)
ClientConnectionId:00000000-0000-0000-0000-000000000000
Error Number:53,State:0,Class:20
 2020-07-31 02:31:25,470 [P5912/D2/T1] INFO  Umbraco.Core.DatabaseContext - CanConnect = False
 2020-07-31 02:31:26,485 [P5912/D2/T1] WARN  Umbraco.Core.Persistence.DbConnectionExtensions - Configured database is reporting as not being available! DataSource: 108.60.212.192, InitialCatalog: LFZ_Web. Exception: System.Data.SqlClient.SqlException (0x80131904): A network-related or instance-specific error occurred while establishing a connection to SQL Server. The server was not found or was not accessible. Verify that the instance name is correct and that SQL Server is configured to allow remote connections. (provider: Named Pipes Provider, error: 40 - Could not open a connection to SQL Server) ---> System.ComponentModel.Win32Exception (0x80004005): The network path was not found
   at System.Data.ProviderBase.DbConnectionPool.TryGetConnection(DbConnection owningObject, UInt32 waitForMultipleObjectsTimeout, Boolean allowCreate, Boolean onlyOneCheckConnection, DbConnectionOptions userOptions, DbConnectionInternal& connection)
   at System.Data.ProviderBase.DbConnectionPool.TryGetConnection(DbConnection owningObject, TaskCompletionSource`1 retry, DbConnectionOptions userOptions, DbConnectionInternal& connection)
   at System.Data.ProviderBase.DbConnectionFactory.TryGetConnection(DbConnection owningConnection, TaskCompletionSource`1 retry, DbConnectionOptions userOptions, DbConnectionInternal oldConnection, DbConnectionInternal& connection)
   at System.Data.ProviderBase.DbConnectionInternal.TryOpenConnectionInternal(DbConnection outerConnection, DbConnectionFactory connectionFactory, TaskCompletionSource`1 retry, DbConnectionOptions userOptions)
   at System.Data.SqlClient.SqlConnection.TryOpenInner(TaskCompletionSource`1 retry)
   at System.Data.SqlClient.SqlConnection.TryOpen(TaskCompletionSource`1 retry)
   at System.Data.SqlClient.SqlConnection.Open()
   at Umbraco.Core.Persistence.DbConnectionExtensions.IsAvailable(IDbConnection connection)
ClientConnectionId:00000000-0000-0000-0000-000000000000
Error Number:53,State:0,Class:20
 2020-07-31 02:31:26,485 [P5912/D2/T1] INFO  Umbraco.Core.DatabaseContext - CanConnect = False
 2020-07-31 02:31:27,501 [P5912/D2/T1] WARN  Umbraco.Core.Persistence.DbConnectionExtensions - Configured database is reporting as not being available! DataSource: 108.60.212.192, InitialCatalog: LFZ_Web. Exception: System.Data.SqlClient.SqlException (0x80131904): A network-related or instance-specific error occurred while establishing a connection to SQL Server. The server was not found or was not accessible. Verify that the instance name is correct and that SQL Server is configured to allow remote connections. (provider: Named Pipes Provider, error: 40 - Could not open a connection to SQL Server) ---> System.ComponentModel.Win32Exception (0x80004005): The network path was not found
   at System.Data.ProviderBase.DbConnectionPool.TryGetConnection(DbConnection owningObject, UInt32 waitForMultipleObjectsTimeout, Boolean allowCreate, Boolean onlyOneCheckConnection, DbConnectionOptions userOptions, DbConnectionInternal& connection)
   at System.Data.ProviderBase.DbConnectionPool.TryGetConnection(DbConnection owningObject, TaskCompletionSource`1 retry, DbConnectionOptions userOptions, DbConnectionInternal& connection)
   at System.Data.ProviderBase.DbConnectionFactory.TryGetConnection(DbConnection owningConnection, TaskCompletionSource`1 retry, DbConnectionOptions userOptions, DbConnectionInternal oldConnection, DbConnectionInternal& connection)
   at System.Data.ProviderBase.DbConnectionInternal.TryOpenConnectionInternal(DbConnection outerConnection, DbConnectionFactory connectionFactory, TaskCompletionSource`1 retry, DbConnectionOptions userOptions)
   at System.Data.SqlClient.SqlConnection.TryOpenInner(TaskCompletionSource`1 retry)
   at System.Data.SqlClient.SqlConnection.TryOpen(TaskCompletionSource`1 retry)
   at System.Data.SqlClient.SqlConnection.Open()
   at Umbraco.Core.Persistence.DbConnectionExtensions.IsAvailable(IDbConnection connection)
ClientConnectionId:00000000-0000-0000-0000-000000000000
Error Number:53,State:0,Class:20
 2020-07-31 02:31:27,501 [P5912/D2/T1] INFO  Umbraco.Core.DatabaseContext - CanConnect = False
 2020-07-31 02:31:28,516 [P5912/D2/T1] WARN  Umbraco.Core.Persistence.DbConnectionExtensions - Configured database is reporting as not being available! DataSource: 108.60.212.192, InitialCatalog: LFZ_Web. Exception: System.Data.SqlClient.SqlException (0x80131904): A network-related or instance-specific error occurred while establishing a connection to SQL Server. The server was not found or was not accessible. Verify that the instance name is correct and that SQL Server is configured to allow remote connections. (provider: Named Pipes Provider, error: 40 - Could not open a connection to SQL Server) ---> System.ComponentModel.Win32Exception (0x80004005): The network path was not found
   at System.Data.ProviderBase.DbConnectionPool.TryGetConnection(DbConnection owningObject, UInt32 waitForMultipleObjectsTimeout, Boolean allowCreate, Boolean onlyOneCheckConnection, DbConnectionOptions userOptions, DbConnectionInternal& connection)
   at System.Data.ProviderBase.DbConnectionPool.TryGetConnection(DbConnection owningObject, TaskCompletionSource`1 retry, DbConnectionOptions userOptions, DbConnectionInternal& connection)
   at System.Data.ProviderBase.DbConnectionFactory.TryGetConnection(DbConnection owningConnection, TaskCompletionSource`1 retry, DbConnectionOptions userOptions, DbConnectionInternal oldConnection, DbConnectionInternal& connection)
   at System.Data.ProviderBase.DbConnectionInternal.TryOpenConnectionInternal(DbConnection outerConnection, DbConnectionFactory connectionFactory, TaskCompletionSource`1 retry, DbConnectionOptions userOptions)
   at System.Data.SqlClient.SqlConnection.TryOpenInner(TaskCompletionSource`1 retry)
   at System.Data.SqlClient.SqlConnection.TryOpen(TaskCompletionSource`1 retry)
   at System.Data.SqlClient.SqlConnection.Open()
   at Umbraco.Core.Persistence.DbConnectionExtensions.IsAvailable(IDbConnection connection)
ClientConnectionId:00000000-0000-0000-0000-000000000000
Error Number:53,State:0,Class:20
 2020-07-31 02:31:28,516 [P5912/D2/T1] INFO  Umbraco.Core.DatabaseContext - CanConnect = False
 2020-07-31 02:31:45,157 [P5912/D2/T1] WARN  Umbraco.Core.Persistence.DbConnectionExtensions - Configured database is reporting as not being available! DataSource: 108.60.212.192, InitialCatalog: LFZ_Web. Exception: System.Data.SqlClient.SqlException (0x80131904): A network-related or instance-specific error occurred while establishing a connection to SQL Server. The server was not found or was not accessible. Verify that the instance name is correct and that SQL Server is configured to allow remote connections. (provider: Named Pipes Provider, error: 40 - Could not open a connection to SQL Server) ---> System.ComponentModel.Win32Exception (0x80004005): The network path was not found
   at System.Data.SqlClient.SqlInternalConnectionTds..ctor(DbConnectionPoolIdentity identity, SqlConnectionString connectionOptions, SqlCredential credential, Object providerInfo, String newPassword, SecureString newSecurePassword, Boolean redirectedUserInstance, SqlConnectionString userConnectionOptions, SessionData reconnectSessionData, DbConnectionPool pool, String accessToken, Boolean applyTransientFaultHandling, SqlAuthenticationProviderManager sqlAuthProviderManager)
   at System.Data.SqlClient.SqlConnectionFactory.CreateConnection(DbConnectionOptions options, DbConnectionPoolKey poolKey, Object poolGroupProviderInfo, DbConnectionPool pool, DbConnection owningConnection, DbConnectionOptions userOptions)
   at System.Data.ProviderBase.DbConnectionFactory.CreatePooledConnection(DbConnectionPool pool, DbConnection owningObject, DbConnectionOptions options, DbConnectionPoolKey poolKey, DbConnectionOptions userOptions)
   at System.Data.ProviderBase.DbConnectionPool.CreateObject(DbConnection owningObject, DbConnectionOptions userOptions, DbConnectionInternal oldConnection)
   at System.Data.ProviderBase.DbConnectionPool.UserCreateRequest(DbConnection owningObject, DbConnectionOptions userOptions, DbConnectionInternal oldConnection)
   at System.Data.ProviderBase.DbConnectionPool.TryGetConnection(DbConnection owningObject, UInt32 waitForMultipleObjectsTimeout, Boolean allowCreate, Boolean onlyOneCheckConnection, DbConnectionOptions userOptions, DbConnectionInternal& connection)
   at System.Data.ProviderBase.DbConnectionPool.TryGetConnection(DbConnection owningObject, TaskCompletionSource`1 retry, DbConnectionOptions userOptions, DbConnectionInternal& connection)
   at System.Data.ProviderBase.DbConnectionFactory.TryGetConnection(DbConnection owningConnection, TaskCompletionSource`1 retry, DbConnectionOptions userOptions, DbConnectionInternal oldConnection, DbConnectionInternal& connection)
   at System.Data.ProviderBase.DbConnectionInternal.TryOpenConnectionInternal(DbConnection outerConnection, DbConnectionFactory connectionFactory, TaskCompletionSource`1 retry, DbConnectionOptions userOptions)
   at System.Data.SqlClient.SqlConnection.TryOpenInner(TaskCompletionSource`1 retry)
   at System.Data.SqlClient.SqlConnection.TryOpen(TaskCompletionSource`1 retry)
   at System.Data.SqlClient.SqlConnection.Open()
   at Umbraco.Core.Persistence.DbConnectionExtensions.IsAvailable(IDbConnection connection)
ClientConnectionId:00000000-0000-0000-0000-000000000000
Error Number:53,State:0,Class:20
 2020-07-31 02:31:45,157 [P5912/D2/T1] INFO  Umbraco.Core.DatabaseContext - CanConnect = False
 2020-07-31 02:31:45,157 [P5912/D2/T1] ERROR Umbraco.Core.UmbracoApplicationBase - An unhandled exception occurred
Umbraco.Core.Exceptions.UmbracoStartupFailedException: Umbraco cannot start. A connection string is configured but Umbraco cannot connect to the database.
   at Umbraco.Core.CoreBootManager.EnsureDatabaseConnection()
   at Umbraco.Core.CoreBootManager.Complete(Action`1 afterComplete)
   at Umbraco.Web.WebBootManager.Complete(Action`1 afterComplete)
   at Umbraco.Core.UmbracoApplicationBase.StartApplication(Object sender, EventArgs e)
 2020-07-31 02:31:55,188 [P5912/D2/T14] INFO  Umbraco.Core.MainDom - Stopping...
 2020-07-31 02:31:55,188 [P5912/D2/T14] INFO  Umbraco.Web.ExamineStartup - Examine shutting down
 2020-07-31 02:31:55,344 [P5912/D2/T14] INFO  Umbraco.Web.ExamineStartup - Complete (took 156ms)
 2020-07-31 02:31:55,344 [P5912/D2/T14] INFO  Umbraco.Core.MainDom - Released MainDom.
 2020-07-31 02:32:25,375 [P5912/D2/T11] INFO  Umbraco.Core.UmbracoApplicationBase - Application shutdown. Details: InitializationError

_shutDownMessage=Initialization Error
HostingEnvironment initiated shutdown
HostingEnvironment caused shutdown

_shutDownStack=   at System.Environment.GetStackTrace(Exception e, Boolean needFileInfo)
   at System.Environment.get_StackTrace()
   at System.Web.Hosting.HostingEnvironment.InitiateShutdownInternal()
   at System.Web.Hosting.HostingEnvironment.InitiateShutdownWithoutDemand()
   at System.Web.HttpRuntime.ShutdownAppDomain(String stackTrace)
   at System.Web.HttpRuntime.AppDomainShutdownTimerCallback(Object state)
   at System.Threading.ExecutionContext.RunInternal(ExecutionContext executionContext, ContextCallback callback, Object state, Boolean preserveSyncCtx)
   at System.Threading.ExecutionContext.Run(ExecutionContext executionContext, ContextCallback callback, Object state, Boolean preserveSyncCtx)
   at System.Threading.TimerQueueTimer.CallCallback()
   at System.Threading.TimerQueueTimer.Fire()
   at System.Threading.TimerQueue.FireNextTimers()
 2020-07-31 02:36:00,671 [P5912/D3/T1] INFO  Umbraco.Core.CoreBootManager - Umbraco 7.10.0 application starting on IP-208-109-15-4
 2020-07-31 02:36:00,686 [P5912/D3/T1] INFO  Umbraco.Core.PluginManager - Determining hash of code files on disk
 2020-07-31 02:36:00,686 [P5912/D3/T1] INFO  Umbraco.Core.PluginManager - Hash determined (took 11ms)
 2020-07-31 02:36:00,733 [P5912/D3/T1] INFO  Umbraco.Core.MainDom - Acquiring MainDom...
 2020-07-31 02:36:00,749 [P5912/D3/T1] INFO  Umbraco.Core.MainDom - Acquired MainDom.
 2020-07-31 02:36:00,749 [P5912/D3/T1] INFO  Umbraco.Core.PluginManager - Resolving umbraco.interfaces.IDiscoverable
 2020-07-31 02:36:00,811 [P5912/D3/T1] INFO  Umbraco.Core.PluginManager - Resolved umbraco.interfaces.IDiscoverable (took 63ms)
 2020-07-31 02:36:00,811 [P5912/D3/T1] INFO  Umbraco.Core.PluginManager - Resolving umbraco.interfaces.IApplicationStartupHandler
 2020-07-31 02:36:00,811 [P5912/D3/T1] INFO  Umbraco.Core.PluginManager - Resolved umbraco.interfaces.IApplicationStartupHandler (took 1ms)
 2020-07-31 02:36:00,843 [P5912/D3/T1] INFO  Umbraco.Core.PluginManager - Resolving umbraco.interfaces.IDiscoverable
 2020-07-31 02:36:00,858 [P5912/D3/T1] INFO  Umbraco.Core.PluginManager - Resolved umbraco.interfaces.IDiscoverable (took 2ms)
 2020-07-31 02:36:00,858 [P5912/D3/T1] INFO  Umbraco.Core.PluginManager - Resolving Umbraco.Core.PropertyEditors.IPropertyEditorValueConverter
 2020-07-31 02:36:00,858 [P5912/D3/T1] INFO  Umbraco.Core.PluginManager - Resolved Umbraco.Core.PropertyEditors.IPropertyEditorValueConverter (took 0ms)
 2020-07-31 02:36:00,858 [P5912/D3/T1] INFO  Umbraco.Core.PluginManager - Resolving umbraco.interfaces.IDiscoverable
 2020-07-31 02:36:00,858 [P5912/D3/T1] INFO  Umbraco.Core.PluginManager - Resolved umbraco.interfaces.IDiscoverable (took 0ms)
 2020-07-31 02:36:00,858 [P5912/D3/T1] INFO  Umbraco.Core.PluginManager - Resolving Umbraco.Core.PropertyEditors.IPropertyValueConverter
 2020-07-31 02:36:00,858 [P5912/D3/T1] INFO  Umbraco.Core.PluginManager - Resolved Umbraco.Core.PropertyEditors.IPropertyValueConverter (took 2ms)
 2020-07-31 02:36:00,858 [P5912/D3/T1] INFO  Umbraco.Core.PluginManager - Resolving umbraco.interfaces.IDiscoverable
 2020-07-31 02:36:00,858 [P5912/D3/T1] INFO  Umbraco.Core.PluginManager - Resolved umbraco.interfaces.IDiscoverable (took 0ms)
 2020-07-31 02:36:00,858 [P5912/D3/T1] INFO  Umbraco.Core.PluginManager - Resolving Umbraco.Web.Mvc.SurfaceController
 2020-07-31 02:36:00,858 [P5912/D3/T1] INFO  Umbraco.Core.PluginManager - Resolved Umbraco.Web.Mvc.SurfaceController (took 0ms)
 2020-07-31 02:36:00,858 [P5912/D3/T1] INFO  Umbraco.Core.PluginManager - Resolving umbraco.interfaces.IDiscoverable
 2020-07-31 02:36:00,858 [P5912/D3/T1] INFO  Umbraco.Core.PluginManager - Resolved umbraco.interfaces.IDiscoverable (took 0ms)
 2020-07-31 02:36:00,858 [P5912/D3/T1] INFO  Umbraco.Core.PluginManager - Resolving Umbraco.Web.WebApi.UmbracoApiController
 2020-07-31 02:36:00,858 [P5912/D3/T1] INFO  Umbraco.Core.PluginManager - Resolved Umbraco.Web.WebApi.UmbracoApiController (took 0ms)
 2020-07-31 02:36:26,967 [P5912/D3/T1] WARN  Umbraco.Core.Persistence.DbConnectionExtensions - Configured database is reporting as not being available! DataSource: 108.60.212.192, InitialCatalog: LFZ_Web. Exception: System.Data.SqlClient.SqlException (0x80131904): A network-related or instance-specific error occurred while establishing a connection to SQL Server. The server was not found or was not accessible. Verify that the instance name is correct and that SQL Server is configured to allow remote connections. (provider: Named Pipes Provider, error: 40 - Could not open a connection to SQL Server) ---> System.ComponentModel.Win32Exception (0x80004005): The network path was not found
   at System.Data.SqlClient.SqlInternalConnectionTds..ctor(DbConnectionPoolIdentity identity, SqlConnectionString connectionOptions, SqlCredential credential, Object providerInfo, String newPassword, SecureString newSecurePassword, Boolean redirectedUserInstance, SqlConnectionString userConnectionOptions, SessionData reconnectSessionData, DbConnectionPool pool, String accessToken, Boolean applyTransientFaultHandling, SqlAuthenticationProviderManager sqlAuthProviderManager)
   at System.Data.SqlClient.SqlConnectionFactory.CreateConnection(DbConnectionOptions options, DbConnectionPoolKey poolKey, Object poolGroupProviderInfo, DbConnectionPool pool, DbConnection owningConnection, DbConnectionOptions userOptions)
   at System.Data.ProviderBase.DbConnectionFactory.CreatePooledConnection(DbConnectionPool pool, DbConnection owningObject, DbConnectionOptions options, DbConnectionPoolKey poolKey, DbConnectionOptions userOptions)
   at System.Data.ProviderBase.DbConnectionPool.CreateObject(DbConnection owningObject, DbConnectionOptions userOptions, DbConnectionInternal oldConnection)
   at System.Data.ProviderBase.DbConnectionPool.UserCreateRequest(DbConnection owningObject, DbConnectionOptions userOptions, DbConnectionInternal oldConnection)
   at System.Data.ProviderBase.DbConnectionPool.TryGetConnection(DbConnection owningObject, UInt32 waitForMultipleObjectsTimeout, Boolean allowCreate, Boolean onlyOneCheckConnection, DbConnectionOptions userOptions, DbConnectionInternal& connection)
   at System.Data.ProviderBase.DbConnectionPool.TryGetConnection(DbConnection owningObject, TaskCompletionSource`1 retry, DbConnectionOptions userOptions, DbConnectionInternal& connection)
   at System.Data.ProviderBase.DbConnectionFactory.TryGetConnection(DbConnection owningConnection, TaskCompletionSource`1 retry, DbConnectionOptions userOptions, DbConnectionInternal oldConnection, DbConnectionInternal& connection)
   at System.Data.ProviderBase.DbConnectionInternal.TryOpenConnectionInternal(DbConnection outerConnection, DbConnectionFactory connectionFactory, TaskCompletionSource`1 retry, DbConnectionOptions userOptions)
   at System.Data.SqlClient.SqlConnection.TryOpenInner(TaskCompletionSource`1 retry)
   at System.Data.SqlClient.SqlConnection.TryOpen(TaskCompletionSource`1 retry)
   at System.Data.SqlClient.SqlConnection.Open()
   at Umbraco.Core.Persistence.DbConnectionExtensions.IsAvailable(IDbConnection connection)
ClientConnectionId:00000000-0000-0000-0000-000000000000
Error Number:53,State:0,Class:20
 2020-07-31 02:36:26,967 [P5912/D3/T1] INFO  Umbraco.Core.DatabaseContext - CanConnect = False
 2020-07-31 02:36:27,124 [P5912/D3/T1] WARN  Umbraco.Core.Persistence.DbConnectionExtensions - Configured database is reporting as not being available! DataSource: 108.60.212.192, InitialCatalog: LFZ_Web. Exception: System.Data.SqlClient.SqlException (0x80131904): A network-related or instance-specific error occurred while establishing a connection to SQL Server. The server was not found or was not accessible. Verify that the instance name is correct and that SQL Server is configured to allow remote connections. (provider: Named Pipes Provider, error: 40 - Could not open a connection to SQL Server) ---> System.ComponentModel.Win32Exception (0x80004005): The network path was not found
   at System.Data.ProviderBase.DbConnectionPool.TryGetConnection(DbConnection owningObject, UInt32 waitForMultipleObjectsTimeout, Boolean allowCreate, Boolean onlyOneCheckConnection, DbConnectionOptions userOptions, DbConnectionInternal& connection)
   at System.Data.ProviderBase.DbConnectionPool.TryGetConnection(DbConnection owningObject, TaskCompletionSource`1 retry, DbConnectionOptions userOptions, DbConnectionInternal& connection)
   at System.Data.ProviderBase.DbConnectionFactory.TryGetConnection(DbConnection owningConnection, TaskCompletionSource`1 retry, DbConnectionOptions userOptions, DbConnectionInternal oldConnection, DbConnectionInternal& connection)
   at System.Data.ProviderBase.DbConnectionInternal.TryOpenConnectionInternal(DbConnection outerConnection, DbConnectionFactory connectionFactory, TaskCompletionSource`1 retry, DbConnectionOptions userOptions)
   at System.Data.SqlClient.SqlConnection.TryOpenInner(TaskCompletionSource`1 retry)
   at System.Data.SqlClient.SqlConnection.TryOpen(TaskCompletionSource`1 retry)
   at System.Data.SqlClient.SqlConnection.Open()
   at Umbraco.Core.Persistence.DbConnectionExtensions.IsAvailable(IDbConnection connection)
ClientConnectionId:00000000-0000-0000-0000-000000000000
Error Number:53,State:0,Class:20
 2020-07-31 02:36:27,124 [P5912/D3/T1] INFO  Umbraco.Core.DatabaseContext - CanConnect = False
 2020-07-31 02:36:28,139 [P5912/D3/T1] WARN  Umbraco.Core.Persistence.DbConnectionExtensions - Configured database is reporting as not being available! DataSource: 108.60.212.192, InitialCatalog: LFZ_Web. Exception: System.Data.SqlClient.SqlException (0x80131904): A network-related or instance-specific error occurred while establishing a connection to SQL Server. The server was not found or was not accessible. Verify that the instance name is correct and that SQL Server is configured to allow remote connections. (provider: Named Pipes Provider, error: 40 - Could not open a connection to SQL Server) ---> System.ComponentModel.Win32Exception (0x80004005): The network path was not found
   at System.Data.ProviderBase.DbConnectionPool.TryGetConnection(DbConnection owningObject, UInt32 waitForMultipleObjectsTimeout, Boolean allowCreate, Boolean onlyOneCheckConnection, DbConnectionOptions userOptions, DbConnectionInternal& connection)
   at System.Data.ProviderBase.DbConnectionPool.TryGetConnection(DbConnection owningObject, TaskCompletionSource`1 retry, DbConnectionOptions userOptions, DbConnectionInternal& connection)
   at System.Data.ProviderBase.DbConnectionFactory.TryGetConnection(DbConnection owningConnection, TaskCompletionSource`1 retry, DbConnectionOptions userOptions, DbConnectionInternal oldConnection, DbConnectionInternal& connection)
   at System.Data.ProviderBase.DbConnectionInternal.TryOpenConnectionInternal(DbConnection outerConnection, DbConnectionFactory connectionFactory, TaskCompletionSource`1 retry, DbConnectionOptions userOptions)
   at System.Data.SqlClient.SqlConnection.TryOpenInner(TaskCompletionSource`1 retry)
   at System.Data.SqlClient.SqlConnection.TryOpen(TaskCompletionSource`1 retry)
   at System.Data.SqlClient.SqlConnection.Open()
   at Umbraco.Core.Persistence.DbConnectionExtensions.IsAvailable(IDbConnection connection)
ClientConnectionId:00000000-0000-0000-0000-000000000000
Error Number:53,State:0,Class:20
 2020-07-31 02:36:28,139 [P5912/D3/T1] INFO  Umbraco.Core.DatabaseContext - CanConnect = False
 2020-07-31 02:36:29,155 [P5912/D3/T1] WARN  Umbraco.Core.Persistence.DbConnectionExtensions - Configured database is reporting as not being available! DataSource: 108.60.212.192, InitialCatalog: LFZ_Web. Exception: System.Data.SqlClient.SqlException (0x80131904): A network-related or instance-specific error occurred while establishing a connection to SQL Server. The server was not found or was not accessible. Verify that the instance name is correct and that SQL Server is configured to allow remote connections. (provider: Named Pipes Provider, error: 40 - Could not open a connection to SQL Server) ---> System.ComponentModel.Win32Exception (0x80004005): The network path was not found
   at System.Data.ProviderBase.DbConnectionPool.TryGetConnection(DbConnection owningObject, UInt32 waitForMultipleObjectsTimeout, Boolean allowCreate, Boolean onlyOneCheckConnection, DbConnectionOptions userOptions, DbConnectionInternal& connection)
   at System.Data.ProviderBase.DbConnectionPool.TryGetConnection(DbConnection owningObject, TaskCompletionSource`1 retry, DbConnectionOptions userOptions, DbConnectionInternal& connection)
   at System.Data.ProviderBase.DbConnectionFactory.TryGetConnection(DbConnection owningConnection, TaskCompletionSource`1 retry, DbConnectionOptions userOptions, DbConnectionInternal oldConnection, DbConnectionInternal& connection)
   at System.Data.ProviderBase.DbConnectionInternal.TryOpenConnectionInternal(DbConnection outerConnection, DbConnectionFactory connectionFactory, TaskCompletionSource`1 retry, DbConnectionOptions userOptions)
   at System.Data.SqlClient.SqlConnection.TryOpenInner(TaskCompletionSource`1 retry)
   at System.Data.SqlClient.SqlConnection.TryOpen(TaskCompletionSource`1 retry)
   at System.Data.SqlClient.SqlConnection.Open()
   at Umbraco.Core.Persistence.DbConnectionExtensions.IsAvailable(IDbConnection connection)
ClientConnectionId:00000000-0000-0000-0000-000000000000
Error Number:53,State:0,Class:20
 2020-07-31 02:36:29,155 [P5912/D3/T1] INFO  Umbraco.Core.DatabaseContext - CanConnect = False
 2020-07-31 02:36:30,174 [P5912/D3/T1] WARN  Umbraco.Core.Persistence.DbConnectionExtensions - Configured database is reporting as not being available! DataSource: 108.60.212.192, InitialCatalog: LFZ_Web. Exception: System.Data.SqlClient.SqlException (0x80131904): A network-related or instance-specific error occurred while establishing a connection to SQL Server. The server was not found or was not accessible. Verify that the instance name is correct and that SQL Server is configured to allow remote connections. (provider: Named Pipes Provider, error: 40 - Could not open a connection to SQL Server) ---> System.ComponentModel.Win32Exception (0x80004005): The network path was not found
   at System.Data.ProviderBase.DbConnectionPool.TryGetConnection(DbConnection owningObject, UInt32 waitForMultipleObjectsTimeout, Boolean allowCreate, Boolean onlyOneCheckConnection, DbConnectionOptions userOptions, DbConnectionInternal& connection)
   at System.Data.ProviderBase.DbConnectionPool.TryGetConnection(DbConnection owningObject, TaskCompletionSource`1 retry, DbConnectionOptions userOptions, DbConnectionInternal& connection)
   at System.Data.ProviderBase.DbConnectionFactory.TryGetConnection(DbConnection owningConnection, TaskCompletionSource`1 retry, DbConnectionOptions userOptions, DbConnectionInternal oldConnection, DbConnectionInternal& connection)
   at System.Data.ProviderBase.DbConnectionInternal.TryOpenConnectionInternal(DbConnection outerConnection, DbConnectionFactory connectionFactory, TaskCompletionSource`1 retry, DbConnectionOptions userOptions)
   at System.Data.SqlClient.SqlConnection.TryOpenInner(TaskCompletionSource`1 retry)
   at System.Data.SqlClient.SqlConnection.TryOpen(TaskCompletionSource`1 retry)
   at System.Data.SqlClient.SqlConnection.Open()
   at Umbraco.Core.Persistence.DbConnectionExtensions.IsAvailable(IDbConnection connection)
ClientConnectionId:00000000-0000-0000-0000-000000000000
Error Number:53,State:0,Class:20
 2020-07-31 02:36:30,174 [P5912/D3/T1] INFO  Umbraco.Core.DatabaseContext - CanConnect = False
 2020-07-31 02:36:31,186 [P5912/D3/T1] WARN  Umbraco.Core.Persistence.DbConnectionExtensions - Configured database is reporting as not being available! DataSource: 108.60.212.192, InitialCatalog: LFZ_Web. Exception: System.Data.SqlClient.SqlException (0x80131904): A network-related or instance-specific error occurred while establishing a connection to SQL Server. The server was not found or was not accessible. Verify that the instance name is correct and that SQL Server is configured to allow remote connections. (provider: Named Pipes Provider, error: 40 - Could not open a connection to SQL Server) ---> System.ComponentModel.Win32Exception (0x80004005): The network path was not found
   at System.Data.ProviderBase.DbConnectionPool.TryGetConnection(DbConnection owningObject, UInt32 waitForMultipleObjectsTimeout, Boolean allowCreate, Boolean onlyOneCheckConnection, DbConnectionOptions userOptions, DbConnectionInternal& connection)
   at System.Data.ProviderBase.DbConnectionPool.TryGetConnection(DbConnection owningObject, TaskCompletionSource`1 retry, DbConnectionOptions userOptions, DbConnectionInternal& connection)
   at System.Data.ProviderBase.DbConnectionFactory.TryGetConnection(DbConnection owningConnection, TaskCompletionSource`1 retry, DbConnectionOptions userOptions, DbConnectionInternal oldConnection, DbConnectionInternal& connection)
   at System.Data.ProviderBase.DbConnectionInternal.TryOpenConnectionInternal(DbConnection outerConnection, DbConnectionFactory connectionFactory, TaskCompletionSource`1 retry, DbConnectionOptions userOptions)
   at System.Data.SqlClient.SqlConnection.TryOpenInner(TaskCompletionSource`1 retry)
   at System.Data.SqlClient.SqlConnection.TryOpen(TaskCompletionSource`1 retry)
   at System.Data.SqlClient.SqlConnection.Open()
   at Umbraco.Core.Persistence.DbConnectionExtensions.IsAvailable(IDbConnection connection)
ClientConnectionId:00000000-0000-0000-0000-000000000000
Error Number:53,State:0,Class:20
 2020-07-31 02:36:31,186 [P5912/D3/T1] INFO  Umbraco.Core.DatabaseContext - CanConnect = False
 2020-07-31 02:36:47,202 [P5912/D3/T1] WARN  Umbraco.Core.Persistence.DbConnectionExtensions - Configured database is reporting as not being available! DataSource: 108.60.212.192, InitialCatalog: LFZ_Web. Exception: System.Data.SqlClient.SqlException (0x80131904): A network-related or instance-specific error occurred while establishing a connection to SQL Server. The server was not found or was not accessible. Verify that the instance name is correct and that SQL Server is configured to allow remote connections. (provider: Named Pipes Provider, error: 40 - Could not open a connection to SQL Server) ---> System.ComponentModel.Win32Exception (0x80004005): The network path was not found
   at System.Data.SqlClient.SqlInternalConnectionTds..ctor(DbConnectionPoolIdentity identity, SqlConnectionString connectionOptions, SqlCredential credential, Object providerInfo, String newPassword, SecureString newSecurePassword, Boolean redirectedUserInstance, SqlConnectionString userConnectionOptions, SessionData reconnectSessionData, DbConnectionPool pool, String accessToken, Boolean applyTransientFaultHandling, SqlAuthenticationProviderManager sqlAuthProviderManager)
   at System.Data.SqlClient.SqlConnectionFactory.CreateConnection(DbConnectionOptions options, DbConnectionPoolKey poolKey, Object poolGroupProviderInfo, DbConnectionPool pool, DbConnection owningConnection, DbConnectionOptions userOptions)
   at System.Data.ProviderBase.DbConnectionFactory.CreatePooledConnection(DbConnectionPool pool, DbConnection owningObject, DbConnectionOptions options, DbConnectionPoolKey poolKey, DbConnectionOptions userOptions)
   at System.Data.ProviderBase.DbConnectionPool.CreateObject(DbConnection owningObject, DbConnectionOptions userOptions, DbConnectionInternal oldConnection)
   at System.Data.ProviderBase.DbConnectionPool.UserCreateRequest(DbConnection owningObject, DbConnectionOptions userOptions, DbConnectionInternal oldConnection)
   at System.Data.ProviderBase.DbConnectionPool.TryGetConnection(DbConnection owningObject, UInt32 waitForMultipleObjectsTimeout, Boolean allowCreate, Boolean onlyOneCheckConnection, DbConnectionOptions userOptions, DbConnectionInternal& connection)
   at System.Data.ProviderBase.DbConnectionPool.TryGetConnection(DbConnection owningObject, TaskCompletionSource`1 retry, DbConnectionOptions userOptions, DbConnectionInternal& connection)
   at System.Data.ProviderBase.DbConnectionFactory.TryGetConnection(DbConnection owningConnection, TaskCompletionSource`1 retry, DbConnectionOptions userOptions, DbConnectionInternal oldConnection, DbConnectionInternal& connection)
   at System.Data.ProviderBase.DbConnectionInternal.TryOpenConnectionInternal(DbConnection outerConnection, DbConnectionFactory connectionFactory, TaskCompletionSource`1 retry, DbConnectionOptions userOptions)
   at System.Data.SqlClient.SqlConnection.TryOpenInner(TaskCompletionSource`1 retry)
   at System.Data.SqlClient.SqlConnection.TryOpen(TaskCompletionSource`1 retry)
   at System.Data.SqlClient.SqlConnection.Open()
   at Umbraco.Core.Persistence.DbConnectionExtensions.IsAvailable(IDbConnection connection)
ClientConnectionId:00000000-0000-0000-0000-000000000000
Error Number:53,State:0,Class:20
 2020-07-31 02:36:47,202 [P5912/D3/T1] INFO  Umbraco.Core.DatabaseContext - CanConnect = False
 2020-07-31 02:36:47,202 [P5912/D3/T1] ERROR Umbraco.Core.UmbracoApplicationBase - An unhandled exception occurred
Umbraco.Core.Exceptions.UmbracoStartupFailedException: Umbraco cannot start. A connection string is configured but Umbraco cannot connect to the database.
   at Umbraco.Core.CoreBootManager.EnsureDatabaseConnection()
   at Umbraco.Core.CoreBootManager.Complete(Action`1 afterComplete)
   at Umbraco.Web.WebBootManager.Complete(Action`1 afterComplete)
   at Umbraco.Core.UmbracoApplicationBase.StartApplication(Object sender, EventArgs e)
 2020-07-31 02:36:57,233 [P5912/D3/T16] INFO  Umbraco.Core.MainDom - Stopping...
 2020-07-31 02:36:57,248 [P5912/D3/T16] INFO  Umbraco.Web.ExamineStartup - Examine shutting down
 2020-07-31 02:36:57,405 [P5912/D3/T16] INFO  Umbraco.Web.ExamineStartup - Complete (took 160ms)
 2020-07-31 02:36:57,405 [P5912/D3/T16] INFO  Umbraco.Core.MainDom - Released MainDom.
 2020-07-31 02:37:27,436 [P5912/D3/T20] INFO  Umbraco.Core.UmbracoApplicationBase - Application shutdown. Details: InitializationError

_shutDownMessage=Initialization Error
HostingEnvironment initiated shutdown
HostingEnvironment caused shutdown

_shutDownStack=   at System.Environment.GetStackTrace(Exception e, Boolean needFileInfo)
   at System.Environment.get_StackTrace()
   at System.Web.Hosting.HostingEnvironment.InitiateShutdownInternal()
   at System.Web.Hosting.HostingEnvironment.InitiateShutdownWithoutDemand()
   at System.Web.HttpRuntime.ShutdownAppDomain(String stackTrace)
   at System.Web.HttpRuntime.AppDomainShutdownTimerCallback(Object state)
   at System.Threading.ExecutionContext.RunInternal(ExecutionContext executionContext, ContextCallback callback, Object state, Boolean preserveSyncCtx)
   at System.Threading.ExecutionContext.Run(ExecutionContext executionContext, ContextCallback callback, Object state, Boolean preserveSyncCtx)
   at System.Threading.TimerQueueTimer.CallCallback()
   at System.Threading.TimerQueueTimer.Fire()
   at System.Threading.TimerQueue.FireNextTimers()
 2020-07-31 03:46:19,688 [P8580/D2/T1] INFO  Umbraco.Core.CoreBootManager - Umbraco 7.10.0 application starting on IP-208-109-15-4
 2020-07-31 03:46:19,719 [P8580/D2/T1] INFO  Umbraco.Core.PluginManager - Determining hash of code files on disk
 2020-07-31 03:46:19,735 [P8580/D2/T1] INFO  Umbraco.Core.PluginManager - Hash determined (took 10ms)
 2020-07-31 03:46:19,829 [P8580/D2/T1] INFO  Umbraco.Core.MainDom - Acquiring MainDom...
 2020-07-31 03:46:19,829 [P8580/D2/T1] INFO  Umbraco.Core.MainDom - Acquired MainDom.
 2020-07-31 03:46:19,829 [P8580/D2/T1] INFO  Umbraco.Core.PluginManager - Resolving umbraco.interfaces.IDiscoverable
 2020-07-31 03:46:19,891 [P8580/D2/T1] INFO  Umbraco.Core.PluginManager - Resolved umbraco.interfaces.IDiscoverable (took 69ms)
 2020-07-31 03:46:19,891 [P8580/D2/T1] INFO  Umbraco.Core.PluginManager - Resolving umbraco.interfaces.IApplicationStartupHandler
 2020-07-31 03:46:19,907 [P8580/D2/T1] INFO  Umbraco.Core.PluginManager - Resolved umbraco.interfaces.IApplicationStartupHandler (took 1ms)
 2020-07-31 03:46:19,938 [P8580/D2/T1] INFO  Umbraco.Core.PluginManager - Resolving umbraco.interfaces.IDiscoverable
 2020-07-31 03:46:19,938 [P8580/D2/T1] INFO  Umbraco.Core.PluginManager - Resolved umbraco.interfaces.IDiscoverable (took 1ms)
 2020-07-31 03:46:19,938 [P8580/D2/T1] INFO  Umbraco.Core.PluginManager - Resolving Umbraco.Core.PropertyEditors.IPropertyEditorValueConverter
 2020-07-31 03:46:19,938 [P8580/D2/T1] INFO  Umbraco.Core.PluginManager - Resolved Umbraco.Core.PropertyEditors.IPropertyEditorValueConverter (took 0ms)
 2020-07-31 03:46:19,938 [P8580/D2/T1] INFO  Umbraco.Core.PluginManager - Resolving umbraco.interfaces.IDiscoverable
 2020-07-31 03:46:19,938 [P8580/D2/T1] INFO  Umbraco.Core.PluginManager - Resolved umbraco.interfaces.IDiscoverable (took 0ms)
 2020-07-31 03:46:19,938 [P8580/D2/T1] INFO  Umbraco.Core.PluginManager - Resolving Umbraco.Core.PropertyEditors.IPropertyValueConverter
 2020-07-31 03:46:19,938 [P8580/D2/T1] INFO  Umbraco.Core.PluginManager - Resolved Umbraco.Core.PropertyEditors.IPropertyValueConverter (took 1ms)
 2020-07-31 03:46:19,954 [P8580/D2/T1] INFO  Umbraco.Core.PluginManager - Resolving umbraco.interfaces.IDiscoverable
 2020-07-31 03:46:19,954 [P8580/D2/T1] INFO  Umbraco.Core.PluginManager - Resolved umbraco.interfaces.IDiscoverable (took 0ms)
 2020-07-31 03:46:19,969 [P8580/D2/T1] INFO  Umbraco.Core.PluginManager - Resolving Umbraco.Web.Mvc.SurfaceController
 2020-07-31 03:46:19,969 [P8580/D2/T1] INFO  Umbraco.Core.PluginManager - Resolved Umbraco.Web.Mvc.SurfaceController (took 0ms)
 2020-07-31 03:46:19,969 [P8580/D2/T1] INFO  Umbraco.Core.PluginManager - Resolving umbraco.interfaces.IDiscoverable
 2020-07-31 03:46:19,969 [P8580/D2/T1] INFO  Umbraco.Core.PluginManager - Resolved umbraco.interfaces.IDiscoverable (took 0ms)
 2020-07-31 03:46:19,969 [P8580/D2/T1] INFO  Umbraco.Core.PluginManager - Resolving Umbraco.Web.WebApi.UmbracoApiController
 2020-07-31 03:46:19,969 [P8580/D2/T1] INFO  Umbraco.Core.PluginManager - Resolved Umbraco.Web.WebApi.UmbracoApiController (took 0ms)
 2020-07-31 03:46:46,469 [P8580/D2/T1] WARN  Umbraco.Core.Persistence.DbConnectionExtensions - Configured database is reporting as not being available! DataSource: 108.60.212.192, InitialCatalog: LFZ_Web. Exception: System.Data.SqlClient.SqlException (0x80131904): A network-related or instance-specific error occurred while establishing a connection to SQL Server. The server was not found or was not accessible. Verify that the instance name is correct and that SQL Server is configured to allow remote connections. (provider: Named Pipes Provider, error: 40 - Could not open a connection to SQL Server) ---> System.ComponentModel.Win32Exception (0x80004005): The network path was not found
   at System.Data.SqlClient.SqlInternalConnectionTds..ctor(DbConnectionPoolIdentity identity, SqlConnectionString connectionOptions, SqlCredential credential, Object providerInfo, String newPassword, SecureString newSecurePassword, Boolean redirectedUserInstance, SqlConnectionString userConnectionOptions, SessionData reconnectSessionData, DbConnectionPool pool, String accessToken, Boolean applyTransientFaultHandling, SqlAuthenticationProviderManager sqlAuthProviderManager)
   at System.Data.SqlClient.SqlConnectionFactory.CreateConnection(DbConnectionOptions options, DbConnectionPoolKey poolKey, Object poolGroupProviderInfo, DbConnectionPool pool, DbConnection owningConnection, DbConnectionOptions userOptions)
   at System.Data.ProviderBase.DbConnectionFactory.CreatePooledConnection(DbConnectionPool pool, DbConnection owningObject, DbConnectionOptions options, DbConnectionPoolKey poolKey, DbConnectionOptions userOptions)
   at System.Data.ProviderBase.DbConnectionPool.CreateObject(DbConnection owningObject, DbConnectionOptions userOptions, DbConnectionInternal oldConnection)
   at System.Data.ProviderBase.DbConnectionPool.UserCreateRequest(DbConnection owningObject, DbConnectionOptions userOptions, DbConnectionInternal oldConnection)
   at System.Data.ProviderBase.DbConnectionPool.TryGetConnection(DbConnection owningObject, UInt32 waitForMultipleObjectsTimeout, Boolean allowCreate, Boolean onlyOneCheckConnection, DbConnectionOptions userOptions, DbConnectionInternal& connection)
   at System.Data.ProviderBase.DbConnectionPool.TryGetConnection(DbConnection owningObject, TaskCompletionSource`1 retry, DbConnectionOptions userOptions, DbConnectionInternal& connection)
   at System.Data.ProviderBase.DbConnectionFactory.TryGetConnection(DbConnection owningConnection, TaskCompletionSource`1 retry, DbConnectionOptions userOptions, DbConnectionInternal oldConnection, DbConnectionInternal& connection)
   at System.Data.ProviderBase.DbConnectionInternal.TryOpenConnectionInternal(DbConnection outerConnection, DbConnectionFactory connectionFactory, TaskCompletionSource`1 retry, DbConnectionOptions userOptions)
   at System.Data.SqlClient.SqlConnection.TryOpenInner(TaskCompletionSource`1 retry)
   at System.Data.SqlClient.SqlConnection.TryOpen(TaskCompletionSource`1 retry)
   at System.Data.SqlClient.SqlConnection.Open()
   at Umbraco.Core.Persistence.DbConnectionExtensions.IsAvailable(IDbConnection connection)
ClientConnectionId:00000000-0000-0000-0000-000000000000
Error Number:53,State:0,Class:20
 2020-07-31 03:46:46,469 [P8580/D2/T1] INFO  Umbraco.Core.DatabaseContext - CanConnect = False
 2020-07-31 03:46:46,641 [P8580/D2/T1] WARN  Umbraco.Core.Persistence.DbConnectionExtensions - Configured database is reporting as not being available! DataSource: 108.60.212.192, InitialCatalog: LFZ_Web. Exception: System.Data.SqlClient.SqlException (0x80131904): A network-related or instance-specific error occurred while establishing a connection to SQL Server. The server was not found or was not accessible. Verify that the instance name is correct and that SQL Server is configured to allow remote connections. (provider: Named Pipes Provider, error: 40 - Could not open a connection to SQL Server) ---> System.ComponentModel.Win32Exception (0x80004005): The network path was not found
   at System.Data.ProviderBase.DbConnectionPool.TryGetConnection(DbConnection owningObject, UInt32 waitForMultipleObjectsTimeout, Boolean allowCreate, Boolean onlyOneCheckConnection, DbConnectionOptions userOptions, DbConnectionInternal& connection)
   at System.Data.ProviderBase.DbConnectionPool.TryGetConnection(DbConnection owningObject, TaskCompletionSource`1 retry, DbConnectionOptions userOptions, DbConnectionInternal& connection)
   at System.Data.ProviderBase.DbConnectionFactory.TryGetConnection(DbConnection owningConnection, TaskCompletionSource`1 retry, DbConnectionOptions userOptions, DbConnectionInternal oldConnection, DbConnectionInternal& connection)
   at System.Data.ProviderBase.DbConnectionInternal.TryOpenConnectionInternal(DbConnection outerConnection, DbConnectionFactory connectionFactory, TaskCompletionSource`1 retry, DbConnectionOptions userOptions)
   at System.Data.SqlClient.SqlConnection.TryOpenInner(TaskCompletionSource`1 retry)
   at System.Data.SqlClient.SqlConnection.TryOpen(TaskCompletionSource`1 retry)
   at System.Data.SqlClient.SqlConnection.Open()
   at Umbraco.Core.Persistence.DbConnectionExtensions.IsAvailable(IDbConnection connection)
ClientConnectionId:00000000-0000-0000-0000-000000000000
Error Number:53,State:0,Class:20
 2020-07-31 03:46:46,641 [P8580/D2/T1] INFO  Umbraco.Core.DatabaseContext - CanConnect = False
 2020-07-31 03:46:47,656 [P8580/D2/T1] WARN  Umbraco.Core.Persistence.DbConnectionExtensions - Configured database is reporting as not being available! DataSource: 108.60.212.192, InitialCatalog: LFZ_Web. Exception: System.Data.SqlClient.SqlException (0x80131904): A network-related or instance-specific error occurred while establishing a connection to SQL Server. The server was not found or was not accessible. Verify that the instance name is correct and that SQL Server is configured to allow remote connections. (provider: Named Pipes Provider, error: 40 - Could not open a connection to SQL Server) ---> System.ComponentModel.Win32Exception (0x80004005): The network path was not found
   at System.Data.ProviderBase.DbConnectionPool.TryGetConnection(DbConnection owningObject, UInt32 waitForMultipleObjectsTimeout, Boolean allowCreate, Boolean onlyOneCheckConnection, DbConnectionOptions userOptions, DbConnectionInternal& connection)
   at System.Data.ProviderBase.DbConnectionPool.TryGetConnection(DbConnection owningObject, TaskCompletionSource`1 retry, DbConnectionOptions userOptions, DbConnectionInternal& connection)
   at System.Data.ProviderBase.DbConnectionFactory.TryGetConnection(DbConnection owningConnection, TaskCompletionSource`1 retry, DbConnectionOptions userOptions, DbConnectionInternal oldConnection, DbConnectionInternal& connection)
   at System.Data.ProviderBase.DbConnectionInternal.TryOpenConnectionInternal(DbConnection outerConnection, DbConnectionFactory connectionFactory, TaskCompletionSource`1 retry, DbConnectionOptions userOptions)
   at System.Data.SqlClient.SqlConnection.TryOpenInner(TaskCompletionSource`1 retry)
   at System.Data.SqlClient.SqlConnection.TryOpen(TaskCompletionSource`1 retry)
   at System.Data.SqlClient.SqlConnection.Open()
   at Umbraco.Core.Persistence.DbConnectionExtensions.IsAvailable(IDbConnection connection)
ClientConnectionId:00000000-0000-0000-0000-000000000000
Error Number:53,State:0,Class:20
 2020-07-31 03:46:47,656 [P8580/D2/T1] INFO  Umbraco.Core.DatabaseContext - CanConnect = False
 2020-07-31 03:46:48,672 [P8580/D2/T1] WARN  Umbraco.Core.Persistence.DbConnectionExtensions - Configured database is reporting as not being available! DataSource: 108.60.212.192, InitialCatalog: LFZ_Web. Exception: System.Data.SqlClient.SqlException (0x80131904): A network-related or instance-specific error occurred while establishing a connection to SQL Server. The server was not found or was not accessible. Verify that the instance name is correct and that SQL Server is configured to allow remote connections. (provider: Named Pipes Provider, error: 40 - Could not open a connection to SQL Server) ---> System.ComponentModel.Win32Exception (0x80004005): The network path was not found
   at System.Data.ProviderBase.DbConnectionPool.TryGetConnection(DbConnection owningObject, UInt32 waitForMultipleObjectsTimeout, Boolean allowCreate, Boolean onlyOneCheckConnection, DbConnectionOptions userOptions, DbConnectionInternal& connection)
   at System.Data.ProviderBase.DbConnectionPool.TryGetConnection(DbConnection owningObject, TaskCompletionSource`1 retry, DbConnectionOptions userOptions, DbConnectionInternal& connection)
   at System.Data.ProviderBase.DbConnectionFactory.TryGetConnection(DbConnection owningConnection, TaskCompletionSource`1 retry, DbConnectionOptions userOptions, DbConnectionInternal oldConnection, DbConnectionInternal& connection)
   at System.Data.ProviderBase.DbConnectionInternal.TryOpenConnectionInternal(DbConnection outerConnection, DbConnectionFactory connectionFactory, TaskCompletionSource`1 retry, DbConnectionOptions userOptions)
   at System.Data.SqlClient.SqlConnection.TryOpenInner(TaskCompletionSource`1 retry)
   at System.Data.SqlClient.SqlConnection.TryOpen(TaskCompletionSource`1 retry)
   at System.Data.SqlClient.SqlConnection.Open()
   at Umbraco.Core.Persistence.DbConnectionExtensions.IsAvailable(IDbConnection connection)
ClientConnectionId:00000000-0000-0000-0000-000000000000
Error Number:53,State:0,Class:20
 2020-07-31 03:46:48,672 [P8580/D2/T1] INFO  Umbraco.Core.DatabaseContext - CanConnect = False
 2020-07-31 03:46:49,688 [P8580/D2/T1] WARN  Umbraco.Core.Persistence.DbConnectionExtensions - Configured database is reporting as not being available! DataSource: 108.60.212.192, InitialCatalog: LFZ_Web. Exception: System.Data.SqlClient.SqlException (0x80131904): A network-related or instance-specific error occurred while establishing a connection to SQL Server. The server was not found or was not accessible. Verify that the instance name is correct and that SQL Server is configured to allow remote connections. (provider: Named Pipes Provider, error: 40 - Could not open a connection to SQL Server) ---> System.ComponentModel.Win32Exception (0x80004005): The network path was not found
   at System.Data.ProviderBase.DbConnectionPool.TryGetConnection(DbConnection owningObject, UInt32 waitForMultipleObjectsTimeout, Boolean allowCreate, Boolean onlyOneCheckConnection, DbConnectionOptions userOptions, DbConnectionInternal& connection)
   at System.Data.ProviderBase.DbConnectionPool.TryGetConnection(DbConnection owningObject, TaskCompletionSource`1 retry, DbConnectionOptions userOptions, DbConnectionInternal& connection)
   at System.Data.ProviderBase.DbConnectionFactory.TryGetConnection(DbConnection owningConnection, TaskCompletionSource`1 retry, DbConnectionOptions userOptions, DbConnectionInternal oldConnection, DbConnectionInternal& connection)
   at System.Data.ProviderBase.DbConnectionInternal.TryOpenConnectionInternal(DbConnection outerConnection, DbConnectionFactory connectionFactory, TaskCompletionSource`1 retry, DbConnectionOptions userOptions)
   at System.Data.SqlClient.SqlConnection.TryOpenInner(TaskCompletionSource`1 retry)
   at System.Data.SqlClient.SqlConnection.TryOpen(TaskCompletionSource`1 retry)
   at System.Data.SqlClient.SqlConnection.Open()
   at Umbraco.Core.Persistence.DbConnectionExtensions.IsAvailable(IDbConnection connection)
ClientConnectionId:00000000-0000-0000-0000-000000000000
Error Number:53,State:0,Class:20
 2020-07-31 03:46:49,688 [P8580/D2/T1] INFO  Umbraco.Core.DatabaseContext - CanConnect = False
 2020-07-31 03:46:50,707 [P8580/D2/T1] WARN  Umbraco.Core.Persistence.DbConnectionExtensions - Configured database is reporting as not being available! DataSource: 108.60.212.192, InitialCatalog: LFZ_Web. Exception: System.Data.SqlClient.SqlException (0x80131904): A network-related or instance-specific error occurred while establishing a connection to SQL Server. The server was not found or was not accessible. Verify that the instance name is correct and that SQL Server is configured to allow remote connections. (provider: Named Pipes Provider, error: 40 - Could not open a connection to SQL Server) ---> System.ComponentModel.Win32Exception (0x80004005): The network path was not found
   at System.Data.ProviderBase.DbConnectionPool.TryGetConnection(DbConnection owningObject, UInt32 waitForMultipleObjectsTimeout, Boolean allowCreate, Boolean onlyOneCheckConnection, DbConnectionOptions userOptions, DbConnectionInternal& connection)
   at System.Data.ProviderBase.DbConnectionPool.TryGetConnection(DbConnection owningObject, TaskCompletionSource`1 retry, DbConnectionOptions userOptions, DbConnectionInternal& connection)
   at System.Data.ProviderBase.DbConnectionFactory.TryGetConnection(DbConnection owningConnection, TaskCompletionSource`1 retry, DbConnectionOptions userOptions, DbConnectionInternal oldConnection, DbConnectionInternal& connection)
   at System.Data.ProviderBase.DbConnectionInternal.TryOpenConnectionInternal(DbConnection outerConnection, DbConnectionFactory connectionFactory, TaskCompletionSource`1 retry, DbConnectionOptions userOptions)
   at System.Data.SqlClient.SqlConnection.TryOpenInner(TaskCompletionSource`1 retry)
   at System.Data.SqlClient.SqlConnection.TryOpen(TaskCompletionSource`1 retry)
   at System.Data.SqlClient.SqlConnection.Open()
   at Umbraco.Core.Persistence.DbConnectionExtensions.IsAvailable(IDbConnection connection)
ClientConnectionId:00000000-0000-0000-0000-000000000000
Error Number:53,State:0,Class:20
 2020-07-31 03:46:50,707 [P8580/D2/T1] INFO  Umbraco.Core.DatabaseContext - CanConnect = False
 2020-07-31 03:47:07,266 [P8580/D2/T1] WARN  Umbraco.Core.Persistence.DbConnectionExtensions - Configured database is reporting as not being available! DataSource: 108.60.212.192, InitialCatalog: LFZ_Web. Exception: System.Data.SqlClient.SqlException (0x80131904): A network-related or instance-specific error occurred while establishing a connection to SQL Server. The server was not found or was not accessible. Verify that the instance name is correct and that SQL Server is configured to allow remote connections. (provider: Named Pipes Provider, error: 40 - Could not open a connection to SQL Server) ---> System.ComponentModel.Win32Exception (0x80004005): The network path was not found
   at System.Data.SqlClient.SqlInternalConnectionTds..ctor(DbConnectionPoolIdentity identity, SqlConnectionString connectionOptions, SqlCredential credential, Object providerInfo, String newPassword, SecureString newSecurePassword, Boolean redirectedUserInstance, SqlConnectionString userConnectionOptions, SessionData reconnectSessionData, DbConnectionPool pool, String accessToken, Boolean applyTransientFaultHandling, SqlAuthenticationProviderManager sqlAuthProviderManager)
   at System.Data.SqlClient.SqlConnectionFactory.CreateConnection(DbConnectionOptions options, DbConnectionPoolKey poolKey, Object poolGroupProviderInfo, DbConnectionPool pool, DbConnection owningConnection, DbConnectionOptions userOptions)
   at System.Data.ProviderBase.DbConnectionFactory.CreatePooledConnection(DbConnectionPool pool, DbConnection owningObject, DbConnectionOptions options, DbConnectionPoolKey poolKey, DbConnectionOptions userOptions)
   at System.Data.ProviderBase.DbConnectionPool.CreateObject(DbConnection owningObject, DbConnectionOptions userOptions, DbConnectionInternal oldConnection)
   at System.Data.ProviderBase.DbConnectionPool.UserCreateRequest(DbConnection owningObject, DbConnectionOptions userOptions, DbConnectionInternal oldConnection)
   at System.Data.ProviderBase.DbConnectionPool.TryGetConnection(DbConnection owningObject, UInt32 waitForMultipleObjectsTimeout, Boolean allowCreate, Boolean onlyOneCheckConnection, DbConnectionOptions userOptions, DbConnectionInternal& connection)
   at System.Data.ProviderBase.DbConnectionPool.TryGetConnection(DbConnection owningObject, TaskCompletionSource`1 retry, DbConnectionOptions userOptions, DbConnectionInternal& connection)
   at System.Data.ProviderBase.DbConnectionFactory.TryGetConnection(DbConnection owningConnection, TaskCompletionSource`1 retry, DbConnectionOptions userOptions, DbConnectionInternal oldConnection, DbConnectionInternal& connection)
   at System.Data.ProviderBase.DbConnectionInternal.TryOpenConnectionInternal(DbConnection outerConnection, DbConnectionFactory connectionFactory, TaskCompletionSource`1 retry, DbConnectionOptions userOptions)
   at System.Data.SqlClient.SqlConnection.TryOpenInner(TaskCompletionSource`1 retry)
   at System.Data.SqlClient.SqlConnection.TryOpen(TaskCompletionSource`1 retry)
   at System.Data.SqlClient.SqlConnection.Open()
   at Umbraco.Core.Persistence.DbConnectionExtensions.IsAvailable(IDbConnection connection)
ClientConnectionId:00000000-0000-0000-0000-000000000000
Error Number:53,State:0,Class:20
 2020-07-31 03:47:07,266 [P8580/D2/T1] INFO  Umbraco.Core.DatabaseContext - CanConnect = False
 2020-07-31 03:47:07,266 [P8580/D2/T1] ERROR Umbraco.Core.UmbracoApplicationBase - An unhandled exception occurred
Umbraco.Core.Exceptions.UmbracoStartupFailedException: Umbraco cannot start. A connection string is configured but Umbraco cannot connect to the database.
   at Umbraco.Core.CoreBootManager.EnsureDatabaseConnection()
   at Umbraco.Core.CoreBootManager.Complete(Action`1 afterComplete)
   at Umbraco.Web.WebBootManager.Complete(Action`1 afterComplete)
   at Umbraco.Core.UmbracoApplicationBase.StartApplication(Object sender, EventArgs e)
 2020-07-31 03:47:17,469 [P8580/D2/T12] INFO  Umbraco.Core.MainDom - Stopping...
 2020-07-31 03:47:17,469 [P8580/D2/T12] INFO  Umbraco.Web.ExamineStartup - Examine shutting down
 2020-07-31 03:47:17,469 [P8580/D2/T12] INFO  Umbraco.Web.ExamineStartup - Complete (took 2ms)
 2020-07-31 03:47:17,469 [P8580/D2/T12] INFO  Umbraco.Core.MainDom - Released MainDom.
 2020-07-31 03:47:47,562 [P8580/D2/T8] INFO  Umbraco.Core.UmbracoApplicationBase - Application shutdown. Details: InitializationError

_shutDownMessage=Initialization Error
HostingEnvironment initiated shutdown
HostingEnvironment caused shutdown

_shutDownStack=   at System.Environment.GetStackTrace(Exception e, Boolean needFileInfo)
   at System.Environment.get_StackTrace()
   at System.Web.Hosting.HostingEnvironment.InitiateShutdownInternal()
   at System.Web.Hosting.HostingEnvironment.InitiateShutdownWithoutDemand()
   at System.Web.HttpRuntime.ShutdownAppDomain(String stackTrace)
   at System.Web.HttpRuntime.AppDomainShutdownTimerCallback(Object state)
   at System.Threading.ExecutionContext.RunInternal(ExecutionContext executionContext, ContextCallback callback, Object state, Boolean preserveSyncCtx)
   at System.Threading.ExecutionContext.Run(ExecutionContext executionContext, ContextCallback callback, Object state, Boolean preserveSyncCtx)
   at System.Threading.TimerQueueTimer.CallCallback()
   at System.Threading.TimerQueueTimer.Fire()
   at System.Threading.TimerQueue.FireNextTimers()
 2020-07-31 04:09:33,819 [P8580/D3/T40] INFO  Umbraco.Core.CoreBootManager - Umbraco 7.10.0 application starting on IP-208-109-15-4
 2020-07-31 04:09:33,850 [P8580/D3/T40] INFO  Umbraco.Core.PluginManager - Determining hash of code files on disk
 2020-07-31 04:09:33,913 [P8580/D3/T40] INFO  Umbraco.Core.PluginManager - Hash determined (took 54ms)
 2020-07-31 04:09:33,928 [P8580/D3/T40] INFO  Umbraco.Core.MainDom - Acquiring MainDom...
 2020-07-31 04:09:33,928 [P8580/D3/T40] INFO  Umbraco.Core.MainDom - Acquired MainDom.
 2020-07-31 04:09:33,928 [P8580/D3/T40] INFO  Umbraco.Core.PluginManager - Resolving umbraco.interfaces.IDiscoverable
 2020-07-31 04:09:33,991 [P8580/D3/T40] INFO  Umbraco.Core.PluginManager - Resolved umbraco.interfaces.IDiscoverable (took 60ms)
 2020-07-31 04:09:33,991 [P8580/D3/T40] INFO  Umbraco.Core.PluginManager - Resolving umbraco.interfaces.IApplicationStartupHandler
 2020-07-31 04:09:33,991 [P8580/D3/T40] INFO  Umbraco.Core.PluginManager - Resolved umbraco.interfaces.IApplicationStartupHandler (took 1ms)
 2020-07-31 04:09:34,022 [P8580/D3/T40] INFO  Umbraco.Core.PluginManager - Resolving umbraco.interfaces.IDiscoverable
 2020-07-31 04:09:34,037 [P8580/D3/T40] INFO  Umbraco.Core.PluginManager - Resolved umbraco.interfaces.IDiscoverable (took 2ms)
 2020-07-31 04:09:34,037 [P8580/D3/T40] INFO  Umbraco.Core.PluginManager - Resolving Umbraco.Core.PropertyEditors.IPropertyEditorValueConverter
 2020-07-31 04:09:34,037 [P8580/D3/T40] INFO  Umbraco.Core.PluginManager - Resolved Umbraco.Core.PropertyEditors.IPropertyEditorValueConverter (took 0ms)
 2020-07-31 04:09:34,037 [P8580/D3/T40] INFO  Umbraco.Core.PluginManager - Resolving umbraco.interfaces.IDiscoverable
 2020-07-31 04:09:34,037 [P8580/D3/T40] INFO  Umbraco.Core.PluginManager - Resolved umbraco.interfaces.IDiscoverable (took 0ms)
 2020-07-31 04:09:34,037 [P8580/D3/T40] INFO  Umbraco.Core.PluginManager - Resolving Umbraco.Core.PropertyEditors.IPropertyValueConverter
 2020-07-31 04:09:34,037 [P8580/D3/T40] INFO  Umbraco.Core.PluginManager - Resolved Umbraco.Core.PropertyEditors.IPropertyValueConverter (took 1ms)
 2020-07-31 04:09:34,069 [P8580/D3/T40] INFO  Umbraco.Core.PluginManager - Resolving umbraco.interfaces.IDiscoverable
 2020-07-31 04:09:34,069 [P8580/D3/T40] INFO  Umbraco.Core.PluginManager - Resolved umbraco.interfaces.IDiscoverable (took 0ms)
 2020-07-31 04:09:34,069 [P8580/D3/T40] INFO  Umbraco.Core.PluginManager - Resolving Umbraco.Web.Mvc.SurfaceController
 2020-07-31 04:09:34,069 [P8580/D3/T40] INFO  Umbraco.Core.PluginManager - Resolved Umbraco.Web.Mvc.SurfaceController (took 0ms)
 2020-07-31 04:09:34,069 [P8580/D3/T40] INFO  Umbraco.Core.PluginManager - Resolving umbraco.interfaces.IDiscoverable
 2020-07-31 04:09:34,069 [P8580/D3/T40] INFO  Umbraco.Core.PluginManager - Resolved umbraco.interfaces.IDiscoverable (took 0ms)
 2020-07-31 04:09:34,069 [P8580/D3/T40] INFO  Umbraco.Core.PluginManager - Resolving Umbraco.Web.WebApi.UmbracoApiController
 2020-07-31 04:09:34,069 [P8580/D3/T40] INFO  Umbraco.Core.PluginManager - Resolved Umbraco.Web.WebApi.UmbracoApiController (took 0ms)
 2020-07-31 04:09:36,350 [P8580/D3/T40] INFO  Umbraco.Core.DatabaseContext - CanConnect = True
 2020-07-31 04:09:36,694 [P8580/D3/T40] INFO  Umbraco.Web.Cache.CacheRefresherEventHandler - Initializing Umbraco internal event handlers for cache refreshing
 2020-07-31 04:09:36,772 [P8580/D3/T40] WARN  Umbraco.Core.Sync.DatabaseServerMessenger - No last synced Id found, this generally means this is a new server/install. The server will build its caches and indexes, and then adjust its last synced Id to the latest found in the database and maintain cache updates based on that Id.
 2020-07-31 04:09:36,803 [P8580/D3/T40] INFO  umbraco.content - Load Xml from file...
 2020-07-31 04:09:36,819 [P8580/D3/T40] INFO  umbraco.content - Loaded Xml from file.
 2020-07-31 04:09:36,819 [P8580/D3/T40] INFO  umbraco.content - Loading content from database...
 2020-07-31 04:09:37,678 [P8580/D3/T40] INFO  UmbracoExamine.DataServices.UmbracoLogService - Rebuilding index, Provider=InternalMemberIndexer, NodeId=-1
 2020-07-31 04:09:37,772 [P8580/D3/T40] INFO  UmbracoExamine.DataServices.UmbracoLogService - PerformIndexAll - Start data queries - member, Provider=InternalMemberIndexer, NodeId=-1
 2020-07-31 04:09:37,959 [P8580/D3/T40] INFO  UmbracoExamine.DataServices.UmbracoLogService - PerformIndexAll - End data queries - member, took 191ms, Provider=InternalMemberIndexer, NodeId=-1
 2020-07-31 04:09:37,959 [P8580/D3/T40] INFO  UmbracoExamine.DataServices.UmbracoLogService - Rebuilding index, Provider=InternalIndexer, NodeId=-1
 2020-07-31 04:09:37,991 [P8580/D3/T40] INFO  UmbracoExamine.DataServices.UmbracoLogService - PerformIndexAll - Start data queries - content, Provider=InternalIndexer, NodeId=-1
 2020-07-31 04:09:38,272 [P8580/D3/T40] INFO  Umbraco.Core.PluginManager - Resolving umbraco.interfaces.IDiscoverable
 2020-07-31 04:09:38,272 [P8580/D3/T40] INFO  Umbraco.Core.PluginManager - Resolved umbraco.interfaces.IDiscoverable (took 0ms)
 2020-07-31 04:09:38,272 [P8580/D3/T40] INFO  Umbraco.Core.PluginManager - Resolving Umbraco.Core.PropertyEditors.IParameterEditor
 2020-07-31 04:09:38,272 [P8580/D3/T40] INFO  Umbraco.Core.PluginManager - Resolved Umbraco.Core.PropertyEditors.IParameterEditor (took 0ms)
 2020-07-31 04:09:38,537 [P8580/D3/T40] INFO  UmbracoExamine.DataServices.UmbracoLogService - PerformIndexAll - End data queries - content, took 557ms, Provider=InternalIndexer, NodeId=-1
 2020-07-31 04:09:38,537 [P8580/D3/T40] INFO  UmbracoExamine.DataServices.UmbracoLogService - PerformIndexAll - Start data queries - media, Provider=InternalIndexer, NodeId=-1
 2020-07-31 04:09:38,772 [P8580/D3/T40] INFO  UmbracoExamine.DataServices.UmbracoLogService - PerformIndexAll - End data queries - media, took 224ms, Provider=InternalIndexer, NodeId=-1
 2020-07-31 04:09:38,772 [P8580/D3/T40] INFO  UmbracoExamine.DataServices.UmbracoLogService - Rebuilding index, Provider=ExternalIndexer, NodeId=-1
 2020-07-31 04:09:38,772 [P8580/D3/T40] INFO  UmbracoExamine.DataServices.UmbracoLogService - PerformIndexAll - Start data queries - content, Provider=ExternalIndexer, NodeId=-1
 2020-07-31 04:09:39,053 [P8580/D3/T40] INFO  UmbracoExamine.DataServices.UmbracoLogService - PerformIndexAll - End data queries - content, took 95ms, Provider=ExternalIndexer, NodeId=-1
 2020-07-31 04:09:39,053 [P8580/D3/T40] INFO  UmbracoExamine.DataServices.UmbracoLogService - PerformIndexAll - Start data queries - media, Provider=ExternalIndexer, NodeId=-1
 2020-07-31 04:09:39,069 [P8580/D3/T40] INFO  UmbracoExamine.DataServices.UmbracoLogService - PerformIndexAll - End data queries - media, took 14ms, Provider=ExternalIndexer, NodeId=-1
 2020-07-31 04:09:39,069 [P8580/D3/T40] INFO  UmbracoExamine.DataServices.UmbracoLogService - Rebuilding index, Provider=FullTextIndexer, NodeId=-1
 2020-07-31 04:09:39,069 [P8580/D3/T40] INFO  UmbracoExamine.DataServices.UmbracoLogService - PerformIndexAll - Start data queries - content, Provider=FullTextIndexer, NodeId=-1
 2020-07-31 04:09:39,131 [P8580/D3/T40] INFO  UmbracoExamine.DataServices.UmbracoLogService - PerformIndexAll - End data queries - content, took 54ms, Provider=FullTextIndexer, NodeId=-1
 2020-07-31 04:09:39,131 [P8580/D3/T40] INFO  UmbracoExamine.DataServices.UmbracoLogService - PerformIndexAll - Start data queries - media, Provider=FullTextIndexer, NodeId=-1
 2020-07-31 04:09:39,272 [P8580/D3/T40] INFO  UmbracoExamine.DataServices.UmbracoLogService - PerformIndexAll - End data queries - media, took 140ms, Provider=FullTextIndexer, NodeId=-1
 2020-07-31 04:09:39,287 [P8580/D3/T40] INFO  Umbraco.Web.Search.ExamineEvents - Initializing Examine and binding to business logic events
 2020-07-31 04:09:39,287 [P8580/D3/T40] INFO  Umbraco.Web.Search.ExamineEvents - Adding examine event handlers for index providers: 4
 2020-07-31 04:09:39,303 [P8580/D3/T40] INFO  Umbraco.Core.CoreBootManager - Umbraco application startup complete (took 5608ms)
 2020-07-31 04:09:39,694 [P8580/D3/T38] INFO  Umbraco.Core.Sync.ApplicationUrlHelper - New ApplicationUrl detected: http://208.109.15.41:80/umbraco
 2020-07-31 04:09:39,694 [P8580/D3/T38] INFO  Umbraco.Core.Sync.ApplicationUrlHelper - ApplicationUrl: http://208.109.15.41:80/umbraco (UmbracoModule request)
 2020-07-31 04:09:41,569 [P8580/D3/T28] INFO  umbraco.content - Save Xml to file...
 2020-07-31 04:09:41,803 [P8580/D3/T28] INFO  umbraco.content - Saved Xml to file.
 2020-07-31 04:09:43,006 [P8580/D3/T38] ERROR Umbraco.ModelsBuilder.Umbraco.PureLiveModelFactory - Failed to build models.
System.Web.HttpCompileException (0x80004005): c:\inetpub\wwwroot\lftzweb_umb\App_Data\Models\all.generated.cs(1613): error CS0542: 'RedirectPage': member names cannot be the same as their enclosing type
   at System.Web.Compilation.AssemblyBuilder.Compile()
   at System.Web.Compilation.BuildProvidersCompiler.PerformBuild()
   at System.Web.Compilation.BuildManager.CompileWebFile(VirtualPath virtualPath)
   at System.Web.Compilation.BuildManager.GetVPathBuildResultInternal(VirtualPath virtualPath, Boolean noBuild, Boolean allowCrossApp, Boolean allowBuildInPrecompile, Boolean throwIfNotFound, Boolean ensureIsUpToDate)
   at System.Web.Compilation.BuildManager.GetVPathBuildResultWithNoAssert(HttpContext context, VirtualPath virtualPath, Boolean noBuild, Boolean allowCrossApp, Boolean allowBuildInPrecompile, Boolean throwIfNotFound, Boolean ensureIsUpToDate)
   at System.Web.Compilation.BuildManager.GetVPathBuildResult(HttpContext context, VirtualPath virtualPath, Boolean noBuild, Boolean allowCrossApp, Boolean allowBuildInPrecompile, Boolean ensureIsUpToDate)
   at System.Web.Compilation.BuildManager.GetCompiledAssembly(String virtualPath)
   at Umbraco.ModelsBuilder.Umbraco.PureLiveModelFactory.GetModelsAssembly(Boolean forceRebuild)
   at Umbraco.ModelsBuilder.Umbraco.PureLiveModelFactory.EnsureModels()
 2020-07-31 04:09:43,006 [P8580/D3/T38] WARN  Umbraco.ModelsBuilder.Umbraco.PureLiveModelFactory - Running without models.
 2020-07-31 04:09:43,522 [P8580/D3/T38] INFO  Umbraco.Core.PluginManager - Resolving umbraco.interfaces.IDiscoverable
 2020-07-31 04:09:43,522 [P8580/D3/T38] INFO  Umbraco.Core.PluginManager - Resolved umbraco.interfaces.IDiscoverable (took 0ms)
 2020-07-31 04:09:43,522 [P8580/D3/T38] INFO  Umbraco.Core.PluginManager - Resolving Umbraco.Core.Deploy.IServiceConnector
 2020-07-31 04:09:43,537 [P8580/D3/T38] INFO  Umbraco.Core.PluginManager - Resolved Umbraco.Core.Deploy.IServiceConnector (took 0ms)
 2020-07-31 04:10:08,006 [P8580/D3/T37] INFO  Umbraco.Core.PluginManager - Resolving umbraco.interfaces.IDiscoverable
 2020-07-31 04:10:08,006 [P8580/D3/T37] INFO  Umbraco.Core.PluginManager - Resolved umbraco.interfaces.IDiscoverable (took 0ms)
 2020-07-31 04:10:08,006 [P8580/D3/T37] INFO  Umbraco.Core.PluginManager - Resolving [Umbraco.Web.Trees.TreeAttribute]Umbraco.Web.Trees.TreeController
 2020-07-31 04:10:08,006 [P8580/D3/T37] INFO  Umbraco.Core.PluginManager - Resolved [Umbraco.Web.Trees.TreeAttribute]Umbraco.Web.Trees.TreeController (took 0ms)
 2020-07-31 04:10:08,756 [P8580/D3/T38] INFO  Umbraco.Core.PluginManager - Resolving umbraco.interfaces.IDiscoverable
 2020-07-31 04:10:08,756 [P8580/D3/T38] INFO  Umbraco.Core.PluginManager - Resolved umbraco.interfaces.IDiscoverable (took 0ms)
 2020-07-31 04:10:08,756 [P8580/D3/T38] INFO  Umbraco.Core.PluginManager - Resolving umbraco.interfaces.IAction
 2020-07-31 04:10:08,756 [P8580/D3/T38] INFO  Umbraco.Core.PluginManager - Resolved umbraco.interfaces.IAction (took 0ms)
 2020-07-31 04:10:28,975 [P8580/D3/T37] INFO  Umbraco.Core.Security.BackOfficeSignInManager - Event Id: 0, state: Login attempt succeeded for username webadmin@ltfz.com from IP address 182.56.29.55
 2020-07-31 04:10:28,975 [P8580/D3/T37] INFO  Umbraco.Core.Security.BackOfficeSignInManager - Event Id: 0, state: User: webadmin@ltfz.com logged in from IP address 182.56.29.55
 2020-07-31 04:10:30,271 [P8580/D3/T26] INFO  Umbraco.Core.PluginManager - Resolving umbraco.interfaces.IDiscoverable
 2020-07-31 04:10:30,271 [P8580/D3/T26] INFO  Umbraco.Core.PluginManager - Resolved umbraco.interfaces.IDiscoverable (took 0ms)
 2020-07-31 04:10:30,271 [P8580/D3/T26] INFO  Umbraco.Core.PluginManager - Resolving umbraco.interfaces.ITree
 2020-07-31 04:10:30,271 [P8580/D3/T26] INFO  Umbraco.Core.PluginManager - Resolved umbraco.interfaces.ITree (took 1ms)
 2020-07-31 04:10:30,303 [P8580/D3/T26] INFO  Umbraco.Core.PluginManager - Resolving umbraco.interfaces.IDiscoverable
 2020-07-31 04:10:30,303 [P8580/D3/T26] INFO  Umbraco.Core.PluginManager - Resolved umbraco.interfaces.IDiscoverable (took 0ms)
 2020-07-31 04:10:30,303 [P8580/D3/T26] INFO  Umbraco.Core.PluginManager - Resolving [Umbraco.Web.Trees.TreeAttribute]Umbraco.Web.Trees.TreeController
 2020-07-31 04:10:30,303 [P8580/D3/T26] INFO  Umbraco.Core.PluginManager - Resolved [Umbraco.Web.Trees.TreeAttribute]Umbraco.Web.Trees.TreeController (took 0ms)
 2020-07-31 04:10:30,303 [P8580/D3/T26] INFO  Umbraco.Core.PluginManager - Resolving umbraco.interfaces.IDiscoverable
 2020-07-31 04:10:30,303 [P8580/D3/T26] INFO  Umbraco.Core.PluginManager - Resolved umbraco.interfaces.IDiscoverable (took 0ms)
 2020-07-31 04:10:30,303 [P8580/D3/T26] INFO  Umbraco.Core.PluginManager - Resolving [umbraco.businesslogic.TreeAttribute]umbraco.interfaces.ITree
 2020-07-31 04:10:30,303 [P8580/D3/T26] INFO  Umbraco.Core.PluginManager - Resolved [umbraco.businesslogic.TreeAttribute]umbraco.interfaces.ITree (took 0ms)
 2020-07-31 04:10:30,318 [P8580/D3/T26] INFO  Umbraco.Core.PluginManager - Resolving umbraco.interfaces.IDiscoverable
 2020-07-31 04:10:30,318 [P8580/D3/T26] INFO  Umbraco.Core.PluginManager - Resolved umbraco.interfaces.IDiscoverable (took 0ms)
 2020-07-31 04:10:30,318 [P8580/D3/T26] INFO  Umbraco.Core.PluginManager - Resolving [umbraco.businesslogic.ApplicationAttribute]umbraco.interfaces.IApplication
 2020-07-31 04:10:30,318 [P8580/D3/T26] INFO  Umbraco.Core.PluginManager - Resolved [umbraco.businesslogic.ApplicationAttribute]umbraco.interfaces.IApplication (took 0ms)
 2020-07-31 04:10:31,771 [P8580/D3/T37] INFO  Umbraco.Core.PluginManager - Resolving umbraco.interfaces.IDiscoverable
 2020-07-31 04:10:31,771 [P8580/D3/T37] INFO  Umbraco.Core.PluginManager - Resolved umbraco.interfaces.IDiscoverable (took 0ms)
 2020-07-31 04:10:31,771 [P8580/D3/T37] INFO  Umbraco.Core.PluginManager - Resolving [Umbraco.Core.Persistence.Mappers.MapperForAttribute]Umbraco.Core.Persistence.Mappers.BaseMapper
 2020-07-31 04:10:31,771 [P8580/D3/T37] INFO  Umbraco.Core.PluginManager - Resolved [Umbraco.Core.Persistence.Mappers.MapperForAttribute]Umbraco.Core.Persistence.Mappers.BaseMapper (took 1ms)
 2020-07-31 04:10:40,162 [P8580/D3/T34] INFO  umbraco.BusinessLogic.Log - Log scrubbed.  Removed all items older than 2020-07-30 04:10:40
 2020-07-31 04:17:02,644 [P8580/D3/T17] INFO  Umbraco.Web.Editors.AuthenticationController - User webadmin@ltfz.com from IP address 182.56.29.55 has logged out
 2020-07-31 04:17:11,441 [P8580/D3/T45] INFO  Umbraco.Core.PluginManager - Resolving umbraco.interfaces.IDiscoverable
 2020-07-31 04:17:11,441 [P8580/D3/T45] INFO  Umbraco.Core.PluginManager - Resolved umbraco.interfaces.IDiscoverable (took 0ms)
 2020-07-31 04:17:11,441 [P8580/D3/T45] INFO  Umbraco.Core.PluginManager - Resolving umbraco.cms.businesslogic.macro.IMacroEngine
 2020-07-31 04:17:11,441 [P8580/D3/T45] INFO  Umbraco.Core.PluginManager - Resolved umbraco.cms.businesslogic.macro.IMacroEngine (took 1ms)
 2020-07-31 08:10:40,201 [P8580/D3/T137] INFO  umbraco.BusinessLogic.Log - Log scrubbed.  Removed all items older than 2020-07-30 08:10:40
 2020-07-31 10:13:51,899 [P8580/D3/T139] WARN  Umbraco.Web.UmbracoModule - Status code is 404 yet TrySkipIisCustomErrors is false - IIS will take over.
 2020-07-31 10:13:52,527 [P8580/D3/T149] WARN  Umbraco.Web.UmbracoModule - Status code is 404 yet TrySkipIisCustomErrors is false - IIS will take over.
 2020-07-31 10:25:41,019 [P8580/D3/T164] INFO  Umbraco.Core.Sync.ApplicationUrlHelper - New ApplicationUrl detected: http://www.practinext.com:80/umbraco
 2020-07-31 10:25:41,019 [P8580/D3/T164] INFO  Umbraco.Core.Sync.ApplicationUrlHelper - ApplicationUrl: http://www.practinext.com:80/umbraco (UmbracoModule request)
 2020-07-31 10:44:18,167 [P8580/D3/T72] WARN  Umbraco.Web.UmbracoModule - Status code is 404 yet TrySkipIisCustomErrors is false - IIS will take over.
 2020-07-31 12:06:07,289 [P8580/D3/T89] WARN  Umbraco.Web.UmbracoModule - Status code is 404 yet TrySkipIisCustomErrors is false - IIS will take over.
 2020-07-31 12:10:40,209 [P8580/D3/T135] INFO  umbraco.BusinessLogic.Log - Log scrubbed.  Removed all items older than 2020-07-30 12:10:40
 2020-07-31 13:41:44,140 [P8580/D3/T166] WARN  Umbraco.Web.UmbracoModule - Status code is 404 yet TrySkipIisCustomErrors is false - IIS will take over.
 2020-07-31 13:41:52,249 [P8580/D3/T166] WARN  Umbraco.Web.UmbracoModule - Status code is 404 yet TrySkipIisCustomErrors is false - IIS will take over.
 2020-07-31 13:45:04,107 [P8580/D3/T150] WARN  Umbraco.Web.UmbracoModule - Status code is 404 yet TrySkipIisCustomErrors is false - IIS will take over.
 2020-07-31 13:45:08,670 [P8580/D3/T132] WARN  Umbraco.Web.UmbracoModule - Status code is 404 yet TrySkipIisCustomErrors is false - IIS will take over.
 2020-07-31 13:45:12,326 [P8580/D3/T163] WARN  Umbraco.Web.UmbracoModule - Status code is 404 yet TrySkipIisCustomErrors is false - IIS will take over.
 2020-07-31 13:51:56,136 [P8580/D3/T11] WARN  Umbraco.Web.UmbracoModule - Status code is 404 yet TrySkipIisCustomErrors is false - IIS will take over.
 2020-07-31 15:58:49,020 [P8580/D3/T95] WARN  Umbraco.Web.UmbracoModule - Status code is 404 yet TrySkipIisCustomErrors is false - IIS will take over.
 2020-07-31 16:10:40,234 [P8580/D3/T263] INFO  umbraco.BusinessLogic.Log - Log scrubbed.  Removed all items older than 2020-07-30 16:10:40
 2020-07-31 18:27:31,677 [P8580/D3/T42] WARN  Umbraco.Web.UmbracoModule - Status code is 404 yet TrySkipIisCustomErrors is false - IIS will take over.
 2020-07-31 20:10:40,242 [P8580/D3/T184] INFO  umbraco.BusinessLogic.Log - Log scrubbed.  Removed all items older than 2020-07-30 20:10:40
 2020-07-31 21:01:24,267 [P8580/D3/T278] INFO  Umbraco.Core.Sync.ApplicationUrlHelper - New ApplicationUrl detected: http://www.medsurveys.in:80/umbraco
 2020-07-31 21:01:24,267 [P8580/D3/T278] INFO  Umbraco.Core.Sync.ApplicationUrlHelper - ApplicationUrl: http://www.medsurveys.in:80/umbraco (UmbracoModule request)
